Workbook

Sheet $_DATA
C1: GREEN CELL MUST BE COMPLETED WITH FORMULAS
M2: Cm | N2: =INT((6+7+4+15+19+26+19)/7) -> 13
C3: FLAIL MOWER BASE PRODUCTION PER YEAR | H3: 125000 | J3: DAYS PER YEAR | K3: 220 | M3: Nm | N3: =INT((13+13+11+25+6+6+13)/7) -> 12
C4: FLAIL MOWER BASE PRODUCTION PER DAY | H4: =ROUNDUP(H3/K3,0) -> 569 | J4: DAYS PER MONTH | K4: 22
C5: FLAIL MOWER BASE PRODUCTION PER MONTH | H5: =ROUNDUP(1.5*(N2+N3)*H4*M6/30,0) -> 15648
K6: DAYS PER MONTH | M6: 22
C7: FLAIL MOWERS TOTAL DEMAND (L=1500 + L=1750) | H7: =H5 -> 15648 | I7: PZ/MONTH | K7: HOURS PER DAY | M7: 15
K8: HOURS PER MONTH | M8: =M6*M7 -> 330
C9: % FLAIL MOWER L=1500 | H9: 0.6 | I9: =ROUNDUP(H7*H9,0) -> 9389
C11: % FLAIL MOWER L=1750 | H11: 0.4 | I11: =ROUNDUP(H7*H11,0) -> 6260
M14: COD. | N14: FLAIL MOWERS WORKCENTERS | S14: AVAILABILITY (A) | T14: PERFORMANCE (P) | U14: QUALITY (Q)
M16: ASS_FIN | N16: FINAL ASSEMBLING | S16: 0.97 | T16: 0.99 | U16: 1
M20: WELD | N20: WELDING DEPARTMENT | S20: 0.98 | T20: 0.97 | U20: 0.97
M26: PSPG | N26: BENDING DEPARTMENT | S26: 0.98 | T26: 0.99 | U26: 0.98
M28: TRNC | N28: STAMPING DEPARTMENT | S28: 0.98 | T28: 0.99 | U28: 0.99
M31: REORDER CYCLE AND SAFETY STOCK OF MATERIALS IN RAW MATERIALS WAREHOUSE | P31: REORDER CYCLE [DAYS] | Q31: SAFETY STOCK [DAYS]
A33: COD | B33: LOAD UNIT TYPE | C33: DESCRIPTION OF MATERIALS IN LOAD UNIT | H33: SIZE A x B x H | J33: PCS/ LOAD UNIT | K33: STACK.
M34: METAL SHEETS | P34: 10 | Q34: 3
A35: ESTLAM001 | B35: PALLET | C35: METAL SHEET 1500x2000x300 | H35: 1500x2000x300 | J35: 25 | K35: 2
A36: ESTLAM002 | B36: PALLET | C36: METAL SHEET 1000x1500x300 | H36: 1000x1500x300 | J36: 25 | K36: 2 | M36: GEARS (CONICAL AND CYLINDRICAL) | P36: 3 | Q36: 1
A37: ESTLAM003 | B37: PALLET | C37: METAL SHEET 1000x2000x300 | H37: 1000x2000x300 | J37: 25 | K37: 2
M38: DRIVE SHAFTS | P38: 10 | Q38: 3
A39: ESTING001 | B39: NORM. | C39: CONICAL GEAR | H39: 800x1000x800 | J39: 200 | K39: 4
A40: ESTING002 | B40: NORM. | C40: CYLINDRICAL GEAR | H40: 800x1000x800 | J40: 200 | K40: 4 | M40: COMPLETE SHAFTS WITH HAMMERS | P40: 5 | Q40: 1
M42: RAKE FOR FLAIL MOWERS | P42: 10 | Q42: 3
A45: INTASS001 | B45: PALLET+BOXES | C45: COMPLETE FLAIL MOWER L=1500 | H45: 1500x2000x1000 | J45: 1 | K45: 2
A46: INTASS002 | B46: PALLET+BOXES | C46: COMPLETE FLAIL MOWER L=1750 | H46: 1500x2000x1000 | J46: 1 | K46: 2 | M46: OPERATION | R46: COD | S46: BATCH [pcs] | T46: SETUP TIME [min] | U46: CYCLE TIME [min]
A47: INTSAL001 | B47: SPEC. | C47: WELDED FLAIL MOWERS FRAME L=1500 | H47: 1500x2000x2000 | J47: 4 | K47: 2 | M47: FINAL ASSEMBLING | O47: FLAIL MOWERS ASSEMBLY L=1500 | R47: INTASS001-10 | S47: 500 | T47: 120 | U47: 2
A48: INTSAL002 | B48: SPEC. | C48: WELDED FLAIL MOWERS FRAME L=1750 | H48: 1500x2000x2000 | J48: 4 | K48: 2 | O48: FLAIL MOWERS ASSEMBLY L=1750 | R48: INTASS002-10 | S48: 215 | T48: 120 | U48: 2
A49: ESTASS003 | B49: SPEC. | C49: COMPLETE HAMMER SHAFT FOR FLAIL MOWERS L=1500 | H49: 1000x2000x1000 | J49: 12 | K49: 4 | M49: WELDING | O49: COMPLETE FRAME. FLAIL MOWERS L=1500 | R49: INTSAL001-10 | S49: 500 | T49: 60 | U49: 8
A50: ESTASS004 | B50: SPEC. | C50: COMPLETE HAMMER SHAFT FOR FLAIL MOWERS L=1750 | H50: 1000x2000x1000 | J50: 12 | K50: 4 | O50: COMPLETE FRAME. FLAIL MOWERS L=1750 | R50: INTSAL002-10 | S50: 215 | T50: 60 | U50: 8
A51: ESTALB001 | B51: NORM. | C51: DRIVE SHAFT L=1500 | H51: 460x800x550 | J51: 50 | K51: 4 | M51: PRESS.BENDING AND BLANKING | O51: BENDING GUARD L=1500 | R51: INTPSP001-20 | S51: 500 | T51: 30 | U51: 1
A52: ESTALB002 | B52: NORM. | C52: DRIVE SHAFT L=1750 | H52: 800x1500x800 | J52: 50 | K52: 4 | O52: GUARD STAMPING L=1500 | R52: INTPSP001-10 | S52: 500 | T52: 30 | U52: 1
O53: BENDING GUARD L=1750 | R53: INTPSP002-20 | S53: 215 | T53: 30 | U53: 1.2
O54: GUARD STAMPING L=1750 | R54: INTPSP002-10 | S54: 215 | T54: 30 | U54: 1.2
A55: INTPSP001-10 | B55: PALLET | C55: STAMPED GUARD FOR L=1500 | H55: 1500x2000x800 | J55: 25 | K55: 1 | O55: BENDING BRACKETS REINFORCEMENT | R55: INTPSP003-20 | S55: 3000 | T55: 30 | U55: 0.3
A56: INTPSP001 | B56: PALLET | C56: BENDED GUARD FOR L=1500 | H56: 1500x2000x800 | J56: 25 | K56: 1 | O56: BRACKETS REINFORCEMENT STAMPING | R56: INTPSP003-10 | S56: 3000 | T56: 30 | U56: 0.3
A57: INTPSP002-10 | B57: PALLET | C57: STAMPED GUARD FOR L=1750 | H57: 1500x2000x800 | J57: 25 | K57: 1 | O57: BENDING BRACKETS HITCH | R57: INTPSP004-20 | S57: 2000 | T57: 30 | U57: 0.5
A58: INTPSP002 | B58: PALLET | C58: BENDED GUARD FOR L=1750 | H58: 1500x2000x800 | J58: 25 | K58: 1 | O58: BRACKETS HITCH STAMPING | R58: INTPSP004-10 | S58: 2000 | T58: 30 | U58: 0.5
A59: INTPSP003-10 | B59: NORM. | C59: STAMPED REINFORCEMENT BRACKETS | H59: 800x1000x800 | J59: 200 | K59: 4
...

Sheet $_BOM_CYCLE
F1: CODE | G1: PADRE | H1: TYPE | I1: DESCRIPTION | J1: USAGE RATE | K1: Q.TY | L1: Q.TY WITH SCRAPS
K2: (pcs/month) | L2: (pcs/month)
A3: BILL OF MATERIAL LEVELS | F3: CODE | G3: FATHER | H3: TYPE | I3: DESCRIPTION | J3: USAGE RATE | K3: Q.TY | L3: Q.TY WITH SCRAPS
A4: 1 | F4: ='$_DATA'!S63 -> INTASS001 | H4: PART | I4: COMPLETE FLAIL MOWERS L=1500 | K4: ='$_DATA'!I9 -> 9389
F5: INTASS001-10 | G5: =F4 -> INTASS001 | H5: OP | I5: COMPLETE FLAIL MOWERS ASSEMBLY L=1500 | L5: =K4/'$_DATA'!U16 -> 9389
B6: 2 | F6: ='$_DATA'!S64 -> INTSAL001 | G6: =F4 -> INTASS001 | H6: PART | I6: COMPLETE FLAIL MOWERS FRAME L=1500 | J6: 1 | K6: =$K4*J6 -> 9389 | P6: =('$_BOM_CYCLE'!K11+'$_BOM_CYCLE'!K32) -> 3285.7972
F7: INTSAL001-10 | G7: =F6 -> INTSAL001 | H7: OP | I7: WELDING FRAME WITH TRACTOR HITCHS L=1500 | L7: =K6/'$_DATA'!U20 -> 9679.3814
C8: 3 | F8: ='$_DATA'!S65 -> INTPSP001 | G8: =F7 -> INTSAL001-10 | H8: PART | I8: GUARD L=1500 | J8: 1 | K8: =L7*J8 -> 9679.3814
F9: INTPSP001-20 | G9: =F8 -> INTPSP001 | H9: OP | I9: GUARD BENDING L=1500 | L9: =K8/'$_DATA'!U26 -> 9876.9198
F10: INTPSP001-10 | G10: =F9 -> INTPSP001-20 | H10: OP | I10: GUARD STAMPING L=1500 | L10: =K8/'$_DATA'!U28 -> 9777.153
D11: 4 | F11: ='$_DATA'!S66 -> ESTLAM001 | G11: =F10 -> INTPSP001-10 | H11: PART | I11: METAL SHEET 1500x2000x3 | J11: 0.17 | K11: =L10/(ROUNDDOWN(1/J11,0)) -> 1955.4306
C12: 3 | F12: ='$_DATA'!S67 -> INTPSP003 | G12: =F7 -> INTSAL001-10 | H12: PART | I12: REINFORCEMENT BRACKETS | J12: 3 | K12: =L7*J12 -> 29038.144
F13: INTPSP003-20 | G13: =F12 -> INTPSP003 | H13: OP | I13: REINFORCEMENT BRACKETS BENDING | L13: =K12/'$_DATA'!U26 -> 29630.76
F14: INTPSP003-10 | G14: =F13 -> INTPSP003-20 | H14: OP | I14: REINFORCEMENT BRACKETS STAMPING | L14: =L13/'$_DATA'!U28 -> 29930.06
D15: 4 | F15: ='$_DATA'!S68 -> ESTLAM002 | G15: =F14 -> INTPSP003-10 | H15: PART | I15: METAL SHEET 1000x1500x3 | J15: 0.05 | K15: =L14/(ROUNDDOWN(1/J15,0)) -> 1496.503
C16: 3 | F16: ='$_DATA'!S69 -> INTPSP004 | G16: =F7 -> INTSAL001-10 | H16: PART | I16: TRACTOR HITCHS PLATES | J16: 2 | K16: =$L$7*J16 -> 19358.763
F17: INTPSP004-20 | G17: =F16 -> INTPSP004 | H17: OP | I17: TRACTOR HITCH BRACKETS BENDING | L17: =K16/'$_DATA'!U26 -> 19753.84
F18: INTPSP004-10 | G18: =F17 -> INTPSP004-20 | H18: OP | I18: TRACTOR HITCHS BRACKETS STAMPING | L18: =L17/'$_DATA'!U28 -> 19953.373
D19: 4 | F19: ='$_DATA'!S70 -> ESTLAM003 | G19: =F18 -> INTPSP004-10 | H19: PART | I19: METAL SHEET 1000x2000x3 | J19: 0.22 | K19: =L18/(ROUNDDOWN(1/J19,0)) -> 4988.3434
C20: 3 | F20: ='$_DATA'!S71 -> ESTSAL001 | G20: =F7 -> INTSAL001-10 | H20: PART | I20: RAKE FOR FLAIL MOWERS L=1500 | J20: 1 | K20: =$L$7*J20 -> 9679.3814
B21: 2 | F21: ='$_DATA'!S72 -> ESTALB001 | G21: =F5 -> INTASS001-10 | H21: PART | I21: DRIVE SHAFT FOR MACHINES L=1500 | J21: 1 | K21: =$L$7*J21 -> 9679.3814
B22: 2 | F22: ='$_DATA'!S73 -> ESTING001 | G22: =F5 -> INTASS001-10 | H22: PART | I22: CONICAL TOOTHED WHEEL | J22: 2 | K22: =$L$7*J22 -> 19358.763
B23: 2 | F23: ='$_DATA'!S74 -> ESTING002 | G23: =F5 -> INTASS001-10 | H23: PART | I23: CYLINDRICAL TOOTHED WHEEL | J23: 3 | K23: =$L$7*J23 -> 29038.144
B24: 2 | F24: ='$_DATA'!S75 -> ESTASS003 | G24: =F5 -> INTASS001-10 | H24: PART | I24: COMPLETE SHAFT WITH HAMMERS FOR FLAIL MOWERS L=1500 | J24: 1 | K24: =$L$7*J24 -> 9679.3814
A25: 1 | F25: ='$_DATA'!S76 -> INTASS002 | G25: GESFAN001 | H25: PART | I25: COMPLETE FLAIL MOWERS L=1750 | K25: ='$_DATA'!I11 -> 6260
F26: INTASS002-10 | G26: =F25 -> INTASS002 | H26: OP | I26: COMPLETE FLAIL MOWERS ASSEMBLY L=1750 | L26: =K25/'$_DATA'!U16 -> 6260
B27: 2 | F27: ='$_DATA'!S77 -> INTSAL002 | G27: =F25 -> INTASS002 | H27: PART | I27: COMPLETE FLAIL MOWERS FRAME L=1750 | J27: 1 | K27: =$K$25*J27 -> 6260
F28: INTSAL002-10 | G28: =F27 -> INTSAL002 | H28: OP | I28: WELDING FRAME. WITH TRACTOR HITCHS L=1750 | L28: =K27/'$_DATA'!U20 -> 6453.6082
C29: 3 | F29: ='$_DATA'!S78 -> INTPSP002 | G29: =F28 -> INTSAL002-10 | H29: PART | I29: GUARD L=1750 | J29: 1 | K29: =$L$28*J29 -> 6453.6082
F30: INTPSP002-20 | G30: =F29 -> INTPSP002 | H30: OP | I30: GUARD BENDING L=1750 | L30: =K29/'$_DATA'!U26 -> 6585.3145
F31: INTPSP002-10 | G31: =F30 -> INTPSP002-20 | H31: OP | I31: GUARD STAMPING L=1750 | L31: =L30/'$_DATA'!U28 -> 6651.8329
D32: 4 | F32: ='$_DATA'!S79 -> ESTLAM001 | G32: =F31 -> INTPSP002-10 | H32: PART | I32: METAL SHEET 1500x2000x3 | J32: 0.2 | K32: =L31/(ROUNDDOWN(1/J32,0)) -> 1330.3666
C33: 3 | F33: ='$_DATA'!S80 -> INTPSP003 | G33: =F28 -> INTSAL002-10 | H33: PART | I33: REINFORCEMENT BRACKETS | J33: 5 | K33: =$L$28*J33 -> 32268.041
F34: INTPSP003-20 | G34: =F33 -> INTPSP003 | H34: OP | I34: REINFORCEMENT BRACKETS BENDING | L34: =K33/'$_DATA'!U26 -> 32926.573
F35: INTPSP003-10 | G35: =F34 -> INTPSP003-20 | H35: OP | I35: REINFORCEMENT BRACKETS STAMPING | L35: =L34/'$_DATA'!U28 -> 33259.164
D36: 4 | F36: ='$_DATA'!S81 -> ESTLAM002 | G36: =F35 -> INTPSP003-10 | H36: PART | I36: METAL SHEET 1000x1500x3 | J36: 0.05 | K36: =L35/(ROUNDDOWN(1/J36,0)) -> 1662.9582
C37: 3 | F37: ='$_DATA'!S82 -> INTPSP004 | G37: =F28 -> INTSAL002-10 | H37: PART | I37: TRACTOR HITCHS PLATES | J37: 2 | K37: =$L$28*J37 -> 12907.216
F38: INTPSP004-20 | G38: =F37 -> INTPSP004 | H38: OP | I38: TRACTOR HITCH BRACKETS BENDING | L38: =K37/'$_DATA'!U26 -> 13170.629
F39: INTPSP004-10 | G39: =F38 -> INTPSP004-20 | H39: OP | I39: TRACTOR HITCHS BRACKETS STAMPING | L39: =L38/'$_DATA'!U28 -> 13303.666
D40: 4 | F40: ='$_DATA'!S83 -> ESTLAM003 | G40: =F39 -> INTPSP004-10 | H40: PART | I40: METAL SHEET 1000x2000x3 | J40: 0.22 | K40: =L39/(ROUNDDOWN(1/J40,0)) -> 3325.9164
...

Sheet $_MANUF_PARTS_BATCH
A1: TOTAL Q.TY (L=1500 + L=1750) | D1: =D2+D3 -> 15649 | E1: PCS/MONTH | F1: =D1/22 -> 711.31818 | G1: PCS PER DAY | H1: ='$_DATA'!M8 -> 330 | I1: HOURS PER MONTH | M1: BATCH [pcs] | N1: SET_UP [min] | O1: TC [min/pcs] | P1: T_POT [min] | Q1: T_AV [min] | R1: T_setup [min] | S1: T_NET [min] | T1: T_PROD [min] | U1: TAKT TIME [min/pcs] | V1: THEORETICAL N LINES OR WS | W1: ACTUAL N LINES OR WS
A2: Q.TY L=1500 | D2: ='$_BOM_CYCLE'!K4 -> 9389 | E2: WORKING DAY PER MONTH | G2: ='$_DATA'!M6 -> 22
A3: Q.TY L=1750 | D3: ='$_BOM_CYCLE'!K25 -> 6260 | E3: HOURS PER DAY | G3: ='$_DATA'!M7 -> 15
A4: OPERATION | C4: CODE | D4: DESCRIPTION | J4: MODEL | L4: TOTAL
J5: L=1500 | K5: L=1750
P6: =
A7: FINAL ASSEMBLING | C7: ='$_BOM_CYCLE'!F5 -> INTASS001-10 | D7: ='$_BOM_CYCLE'!I5 -> COMPLETE FLAIL MOWERS ASSEMBLY L=1500 | J7: ='$_BOM_CYCLE'!L5 -> 9389 | L7: =J7+K7 -> 9389 | M7: ='$_DATA'!S47 -> 500 | N7: ='$_DATA'!T47 -> 120 | O7: ='$_DATA'!U47 -> 2 | P7: =$G$2*$G$3*60 -> 19800 | Q7: ='$_DATA'!S16*P7 -> 19206 | R7: =(L7/M7)*N7 -> 2253.36 | S7: =Q7-R7 -> 16952.64 | T7: =S7*'$_DATA'!T16 -> 16783.114 | U7: =T7/L7 -> 1.7875294 | V7: =O7/U7 -> 1.1188627 | W7: =ROUNDUP(V7+V8,0) -> 2 | Y7: 28
C8: ='$_BOM_CYCLE'!F26 -> INTASS002-10 | D8: ='$_BOM_CYCLE'!I26 -> COMPLETE FLAIL MOWERS ASSEMBLY L=1750 | K8: =D3 -> 6260 | L8: =J8+K8 -> 6260 | M8: 215 | N8: ='$_DATA'!T48 -> 120 | O8: ='$_DATA'!U48 -> 2 | P8: =$G$2*$G$3*60 -> 19800 | Q8: ='$_DATA'!S16*P8 -> 19206 | R8: =(L8/M8)*N8 -> 3493.9535 | S8: =Q8-R8 -> 15712.047 | T8: =S8*'$_DATA'!T16 -> 15554.926 | U8: =T8/L8 -> 2.4848125 | V8: =O8/U8 -> 0.80488972
P9: ='$_MANUF_PARTS_BATCH'!J56 -> 683.56957
A10: WELDING | C10: ='$_BOM_CYCLE'!F7 -> INTSAL001-10 | D10: ='$_BOM_CYCLE'!I7 -> WELDING FRAME WITH TRACTOR HITCHS L=1500 | J10: ='$_BOM_CYCLE'!L7 -> 9679.3814 | L10: =J10+K10 -> 9679.3814 | M10: 500 | N10: ='$_DATA'!T49 -> 60 | O10: ='$_DATA'!U49 -> 8 | P10: =$G$2*$G$3*60 -> 19800 | Q10: ='$_DATA'!S20*P10 -> 19404 | R10: =(L10/M10)*N10 -> 1161.5258 | S10: =Q10-R10 -> 18242.474 | T10: =S10*'$_DATA'!T20 -> 17695.2 | U10: =T10/L10 -> 1.8281333 | V10: =O10/U10 -> 4.3760484 | W10: =ROUNDUP(V10+V11,0) -> 8 | Y10: 112
C11: ='$_BOM_CYCLE'!F28 -> INTSAL002-10 | D11: ='$_BOM_CYCLE'!I28 -> WELDING FRAME. WITH TRACTOR HITCHS L=1750 | K11: ='$_BOM_CYCLE'!L28 -> 6453.6082 | L11: =J11+K11 -> 6453.6082 | M11: 215 | N11: ='$_DATA'!T50 -> 60 | O11: ='$_DATA'!U50 -> 8 | P11: =$G$2*$G$3*60 -> 19800 | Q11: ='$_DATA'!S20*P11 -> 19404 | R11: =(L11/M11)*N11 -> 1801.007 | S11: =Q11-R11 -> 17602.993 | T11: =S11*'$_DATA'!T20 -> 17074.903 | U11: =T11/L11 -> 2.6457917 | V11: =O11/U11 -> 3.0236696
A13: BENDING AND STAMPING | C13: ='$_BOM_CYCLE'!F9 -> INTPSP001-20 | D13: ='$_BOM_CYCLE'!I9 -> GUARD BENDING L=1500 | J13: ='$_BOM_CYCLE'!L9 -> 9876.9198 | L13: =J13+K13 -> 9876.9198 | M13: 500 | N13: ='$_DATA'!T51 -> 30 | O13: ='$_DATA'!U51 -> 1 | P13: =$G$2*$G$3*60 -> 19800 | Q13: ='$_DATA'!$S$26*P13 -> 19404 | R13: =(L13/M13)*N13 -> 592.61519 | S13: =Q13-R13 -> 18811.385 | T13: =S13*'$_DATA'!$T$26 -> 18623.271 | U13: =T13/L13 -> 1.8855343 | V13: =O13/U13 -> 0.53035366 | W13: =ROUNDUP(SUM(V13:V16),0) -> 3 | Y13: 42
C14: ='$_BOM_CYCLE'!F10 -> INTPSP001-10 | D14: ='$_BOM_CYCLE'!I13 -> REINFORCEMENT BRACKETS BENDING | J14: ='$_BOM_CYCLE'!L13 -> 29630.76 | K14: ='$_BOM_CYCLE'!L34 -> 32926.573 | L14: =J14+K14 -> 62557.332 | M14: 3000 | N14: ='$_DATA'!T55 -> 30 | O14: ='$_DATA'!U55 -> 0.3 | P14: =$G$2*$G$3*60 -> 19800 | Q14: ='$_DATA'!$S$26*P14 -> 19404 | R14: =(L14/M14)*N14 -> 625.57332 | S14: =Q14-R14 -> 18778.427 | T14: =S14*'$_DATA'!$T$26 -> 18590.642 | U14: =T14/L14 -> 0.29717767 | V14: =O14/U14 -> 1.0094971
C15: ='$_BOM_CYCLE'!F30 -> INTPSP002-20 | D15: ='$_BOM_CYCLE'!I30 -> GUARD BENDING L=1750 | K15: ='$_BOM_CYCLE'!L30 -> 6585.3145 | L15: =J15+K15 -> 6585.3145 | M15: 215 | N15: ='$_DATA'!T53 -> 30 | O15: ='$_DATA'!U53 -> 1.2 | P15: =$G$2*$G$3*60 -> 19800 | Q15: ='$_DATA'!$S$26*P15 -> 19404 | R15: =(L15/M15)*N15 -> 918.8811 | S15: =Q15-R15 -> 18485.119 | T15: =S15*'$_DATA'!$T$26 -> 18300.268 | U15: =T15/L15 -> 2.7789512 | V15: =O15/U15 -> 0.43181759
C16: ='$_BOM_CYCLE'!F31 -> INTPSP002-10 | D16: ='$_BOM_CYCLE'!I17 -> TRACTOR HITCH BRACKETS BENDING | J16: ='$_BOM_CYCLE'!L17 -> 19753.84 | K16: ='$_BOM_CYCLE'!L38 -> 13170.629 | L16: =J16+K16 -> 32924.469 | M16: 2000 | N16: ='$_DATA'!T57 -> 30 | O16: ='$_DATA'!U57 -> 0.5 | P16: =$G$2*$G$3*60 -> 19800 | Q16: ='$_DATA'!$S$26*P16 -> 19404 | R16: =(L16/M16)*N16 -> 493.86703 | S16: =Q16-R16 -> 18910.133 | T16: =S16*'$_DATA'!$T$26 -> 18721.032 | U16: =T16/L16 -> 0.56860543 | V16: =O16/U16 -> 0.8793444
C17: ='$_BOM_CYCLE'!F13 -> INTPSP003-20 | D17: ='$_BOM_CYCLE'!I10 -> GUARD STAMPING L=1500 | J17: ='$_BOM_CYCLE'!L10 -> 9777.153 | L17: =J17+K17 -> 9777.153 | M17: 500 | N17: ='$_DATA'!T52 -> 30 | O17: ='$_DATA'!U52 -> 1 | P17: =$G$2*$G$3*60 -> 19800 | Q17: ='$_DATA'!$S$28*P17 -> 19404 | R17: =(L17/M17)*N17 -> 586.62918 | S17: =Q17-R17 -> 18817.371 | T17: =S17*'$_DATA'!$T$28 -> 18629.197 | U17: =T17/L17 -> 1.9053806 | V17: =O17/U17 -> 0.52482954 | W17: =ROUNDUP(SUM(V17:V20),0) -> 3 | Y17: 42
C18: INTPSP002-10 | D18: ='$_BOM_CYCLE'!I14 -> REINFORCEMENT BRACKETS STAMPING | J18: ='$_BOM_CYCLE'!L14 -> 29930.06 | K18: ='$_BOM_CYCLE'!L35 -> 33259.164 | L18: =J18+K18 -> 63189.224 | M18: 3000 | N18: ='$_DATA'!T56 -> 30 | O18: ='$_DATA'!U56 -> 0.3 | P18: =$G$2*$G$3*60 -> 19800 | Q18: ='$_DATA'!$S$28*P18 -> 19404 | R18: =(L18/M18)*N18 -> 631.89224 | S18: =Q18-R18 -> 18772.108 | T18: =S18*'$_DATA'!$T$28 -> 18584.387 | U18: =T18/L18 -> 0.2941069 | V18: =O18/U18 -> 1.0200373
C19: ='$_BOM_CYCLE'!F38 -> INTPSP004-20 | D19: ='$_BOM_CYCLE'!I31 -> GUARD STAMPING L=1750 | K19: ='$_BOM_CYCLE'!L31 -> 6651.8329 | L19: =J19+K19 -> 6651.8329 | M19: 215 | N19: ='$_DATA'!T54 -> 30 | O19: ='$_DATA'!U54 -> 1.2 | P19: =$G$2*$G$3*60 -> 19800 | Q19: ='$_DATA'!$S$28*P19 -> 19404 | R19: =(L19/M19)*N19 -> 928.16273 | S19: =Q19-R19 -> 18475.837 | T19: =S19*'$_DATA'!$T$28 -> 18291.079 | U19: =T19/L19 -> 2.7497803 | V19: =O19/U19 -> 0.4363985
C20: ='$_BOM_CYCLE'!F18 -> INTPSP004-10 | D20: ='$_BOM_CYCLE'!I18 -> TRACTOR HITCHS BRACKETS STAMPING | J20: ='$_BOM_CYCLE'!L18 -> 19953.373 | K20: ='$_BOM_CYCLE'!L39 -> 13303.666 | L20: =J20+K20 -> 33257.039 | M20: 2000 | N20: ='$_DATA'!T58 -> 30 | O20: ='$_DATA'!U58 -> 0.5 | P20: =$G$2*$G$3*60 -> 19800 | Q20: ='$_DATA'!$S$28*P20 -> 19404 | R20: =(L20/M20)*N20 -> 498.85559 | S20: =Q20-R20 -> 18905.144 | T20: =S20*'$_DATA'!$T$28 -> 18716.093 | U20: =T20/L20 -> 0.56277087 | V20: =O20/U20 -> 0.88846105
A23: OPERATION | C23: CODE | D23: ITEM DESCRIPTION | J23: CHAINSAW MODEL | L23: TOTAL QTY | M23: THEORETICAL N WS | N23: ACTUL N. LINES EFFETTIVO | O23: ACTUAL N. WS/LINE | P23: T_POT Dep | Q23: T_net Dep | R23: A_Dep | S23: P | T23: SATURAZ% | U23: P_Dep | V23: Q | W23: OEE
J24: P=1.2 Kw | K24: P=1.8 Kw
A26: FINAL ASSEMBLING | C26: =C7 -> INTASS001-10 | D26: =D7 -> COMPLETE FLAIL MOWERS ASSEMBLY L=1500 | J26: =J7 -> 9389 | L26: =L7 -> 9389 | M26: =OP_ASSEMBLING!O17/U7 -> 3.5244175 | N26: =W7 -> 2 | O26: =ROUNDUP(SUM(M26:M27),0) -> 7 | P26: =P7*N26*O26 -> 277200 | Q26: =(S7*M26+S8*M27)/T26 -> 230070.13 | R26: =Q26/P26 -> 0.82997884 | S26: ='$_DATA'!T16 -> 0.99 | T26: =(M26+M27)/(N26*O26) -> 0.4328443 | U26: =T26*S26 -> 0.42851585 | V26: ='$_DATA'!U16 -> 1 | W26: =R26*U26*V26 -> 0.35565909
C27: =C8 -> INTASS002-10 | D27: =D8 -> COMPLETE FLAIL MOWERS ASSEMBLY L=1750 | K27: =K8 -> 6260 | L27: =L8 -> 6260 | M27: =OP_ASSEMBLING!O17/U8 -> 2.5354026
A29: OPERATION | C29: CODE | D29: DESCRIPTION | J29: CHAINSAW MODEL | L29: TOTAL QTY | M29: THEORETICAL N WS | N29: ACTUAL N. WS | P29: T_POT Dep | Q29: T_net Dep | R29: A_Dep | S29: P | T29: SATURAZ% | U29: P_Dep | V29: Q | W29: OEE
J30: P=1.2 Kw | K30: P=1.8 Kw
A32: WELDING | C32: =C10 -> INTSAL001-10 | D32: =D10 -> WELDING FRAME WITH TRACTOR HITCHS L=1500 | J32: =J10 -> 9679.3814 | L32: =L10 -> 9679.3814 | M32: =O10/U10 -> 4.3760484 | N32: =W10 -> 8 | P32: =N32*19800 -> 158400 | Q32: =S10*(M32+M33)/T32 -> 145939.79 | R32: =S10/P10 -> 0.92133708 | S32: ='$_DATA'!T20 -> 0.97 | T32: =(M32+M33)/N32 -> 0.92496475 | U32: =T32*S32 -> 0.89721581 | V32: ='$_DATA'!U20 -> 0.97 | W32: =V32*U32*R32 -> 0.80183905
C33: =C11 -> INTSAL002-10 | D33: =D11 -> WELDING FRAME. WITH TRACTOR HITCHS L=1750 | K33: =K11 -> 6453.6082 | L33: =L11 -> 6453.6082 | M33: =O11/U11 -> 3.0236696
A35: BENDING | C35: =C13 -> INTPSP001-20 | D35: =D13 -> GUARD BENDING L=1500 | J35: =J13 -> 9876.9198 | L35: =L13 -> 9876.9198 | M35: =O13/U13 -> 0.53035366 | N35: =W13 -> 3 | P35: =N35*19800 -> 59400 | Q35: =SUM(M35:M38)*S13/T35 -> 56434.154 | R35: =S13/P13 -> 0.95006994 | S35: ='$_DATA'!T26 -> 0.99 | T35: =SUM(M35:M38)/N35 -> 0.95033758 | U35: =T35*S35 -> 0.94083421 | V35: ='$_DATA'!U26 -> 0.98 | W35: =V35*U35*R35 -> 0.87598113
C36: =C15 -> INTPSP002-20 | D36: =D15 -> GUARD BENDING L=1750 | K36: =K15 -> 6585.3145 | L36: =L15 -> 6585.3145 | M36: =O15/U15 -> 0.43181759
C37: =C17 -> INTPSP003-20 | D37: =D14 -> REINFORCEMENT BRACKETS BENDING | J37: =J14 -> 29630.76 | K37: =K14 -> 32926.573 | L37: =L14 -> 62557.332 | M37: =O14/U14 -> 1.0094971
C38: =C19 -> INTPSP004-20 | D38: =D16 -> TRACTOR HITCH BRACKETS BENDING | J38: =J16 -> 19753.84 | K38: =K16 -> 13170.629 | L38: =L16 -> 32924.469 | M38: =O16/U16 -> 0.8793444
A40: STAMPING | C40: =C14 -> INTPSP001-10 | D40: =D17 -> GUARD STAMPING L=1500 | J40: =J17 -> 9777.153 | L40: =L17 -> 9777.153 | M40: =O17/U17 -> 0.52482954 | N40: =W17 -> 3 | P40: =N40*19800 -> 59400 | Q40: =SUM(M40:M43)*S17/T40 -> 56452.112 | R40: =S17/P17 -> 0.95037226 | S40: ='$_DATA'!T28 -> 0.99 | T40: =SUM(M40:M43)/N40 -> 0.95657546 | U40: =T40*S40 -> 0.9470097 | V40: ='$_DATA'!U28 -> 0.99 | W40: =V40*U40*R40 -> 0.89101164
C41: =C16 -> INTPSP002-10 | D41: =D19 -> GUARD STAMPING L=1750 | K41: =K19 -> 6651.8329 | L41: =L19 -> 6651.8329 | M41: =O19/U19 -> 0.4363985
C42: =C18 -> INTPSP002-10 | D42: =D18 -> REINFORCEMENT BRACKETS STAMPING | J42: =J18 -> 29930.06 | K42: =K18 -> 33259.164 | L42: =L18 -> 63189.224 | M42: =O18/U18 -> 1.0200373
C43: =C20 -> INTPSP004-10 | D43: =D20 -> TRACTOR HITCHS BRACKETS STAMPING | J43: =J20 -> 19953.373 | K43: =K20 -> 13303.666 | L43: =L20 -> 33257.039 | M43: =O20/U20 -> 0.88846105
F47: Assembly | G47: Production per day per machine | K47: Run Time | L47: Setup Time | O47: Welding | P47: Prodduction per day per machine | S47: Run Time | T47: Setup Time | V47: Bending | Y47: Production per day per machine | AC47: Run Time | AD47: Setup Time
F48: L=1500 | G48: =ROUNDUP(L7/(W7*G2),0) -> 214 | K48: =G48*O7 -> 428 | L48: 120 | O48: L=1500 | P48: =ROUNDUP(L10/(W10*G2),0) -> 55 | S48: =P48*O10 -> 440 | T48: 60 | V48: GUARD BENDING L=1500 | Y48: =ROUNDUP(L13/(W13*G2),0) -> 150 | AC48: =O13*Y48 -> 150 | AD48: 30
F49: L=1750 | G49: =ROUNDUP(L8/(W7*G2),0) -> 143 | K49: =G49*O8 -> 286 | L49: 120 | O49: L=1750 | P49: =ROUNDUP(L11/(W10*G2),0) -> 37 | S49: =P49*O11 -> 296 | T49: 60 | V49: REINFORCED BRACKET BENDING | Y49: =ROUNDUP(L14/(W13*G2),0) -> 948 | AC49: =O14*Y49 -> 284.4 | AD49: 30
K50: =SUM(K48:K49) -> 714 | L50: 240 | S50: =SUM(S48:S49) -> 736 | T50: 120 | V50: GUARD BENDING L=1750 | Y50: =ROUNDUP(L15/(W13*G2),0) -> 100 | AC50: =O15*Y50 -> 120 | AD50: 30
G51: PRODUCTION TIME | I51: =900*0.99*0.97 -> 864.27 | P51: PRODUCTION TIME | R51: =900*0.98*0.97 -> 855.54 | V51: TRACTOR HITCH BRACKET BENDING | Y51: =ROUNDUP(L16/(W13*G2),0) -> 499 | AC51: =O16*Y51 -> 249.5 | AD51: 30
...

Sheet $_MOV_MATERIALS
C2: MONTHLY LOAD UNITS MOVEMENTS [LOAD UNITS]
A4: FROM (row) / TO (column) | C4: RM WAREHOUSE | E4: FP WAREHOUSE | G4: FINAL ASSEMBLING | I4: WELDING BUFFER | K4: WELDING | M4: BENDING BUFFER | O4: BENDING | Q4: STAMPING BUFFER | S4: STAMPING
A6: RM WAREHOUSE
A8: FP WAREHOUSE | G8: =C10+I10 -> 4510
A10: FINAL ASSEMBLING | C10: =SUM(E28:J29) -> 2049 | I10: =K12 -> 2461
A12: WELDING BUFFER | K12: =M14+C14 -> 2461
A14: WELDING | C14: =K28 -> 1345 | M14: ='$_WARE_BUFFER'!O23+'$_WARE_BUFFER'!O25+'$_WARE_BUFFER'!O27+'$_WARE_BUFFER'!O29 -> 1116
A16: BENDING BUFFER | O16: ='$_WARE_BUFFER'!O23+'$_WARE_BUFFER'!O25+'$_WARE_BUFFER'!O27+'$_WARE_BUFFER'!O29 -> 1116
A18: BENDING | Q18: ='$_WARE_BUFFER'!O24+'$_WARE_BUFFER'!O26+'$_WARE_BUFFER'!O28+'$_WARE_BUFFER'!O30 -> 1142
A20: STAMPING BUFFER | S20: ='$_WARE_BUFFER'!O24+'$_WARE_BUFFER'!O26+'$_WARE_BUFFER'!O28+'$_WARE_BUFFER'!O30 -> 1142
A22: STAMPING | C22: =C28 -> 507
A26: INPUT PER MONTH [LU/MONTH] IN RM WAREHOUSE | C26: METAL SHEET | E26: GEARS | G26: DRIVE SHAFT | I26: COMPLETE SHAFT WITH HAMMER FOR FLAIL MOWERS | K26: RAKE FOR FLAIL MOWERS
C28: =SUM('$_WARE_BUFFER'!O6:O8) -> 507 | E28: =SUM('$_WARE_BUFFER'!O9:O10) -> 400 | G28: =SUM('$_WARE_BUFFER'!O11:O12) -> 320 | I28: =SUM('$_WARE_BUFFER'!O13:O14) -> 1329 | K28: ='$_WARE_BUFFER'!O15+'$_WARE_BUFFER'!O16 -> 1345
A32: OUTPUT PER MONTH [LU/MONTH] FROM FP WAREHOUSE | C32: FLAIL MOWERS L=1500 | E32: FLAIL MOWERS L=1750 | G32: Departures from the PF warehouse occur daily. The daily quantity is shipped.
C34: ='$_WARE_BUFFER'!O18 -> 9389 | E34: ='$_WARE_BUFFER'!O19 -> 6260
B38: A similar matrix is constructed with distances (A/R) between departments, travel times, and loading/unloading times. All of this makes it possible to calculate the time for a mission. The time per mission multiplied by the number of missions gives the total time spent on a route.
M40: For dock (and reception area) sizing, the worst-case situation is considered in which all component families are received on the same day for the quantities of their respective coverage days
M46: For dock (and shipping area) sizing, the number of daily UDCs is calculated

Sheet $_WARE_BUFFER
A1: TOTAL Q.TY (L=1500 + L=1750) | D1: =D2+D3 -> 15649 | E1: PCS/MONTH | F1: =D1/22 -> 711.31818 | G1: PCS PER DAY | H1: ='$_DATA'!M8 -> 330 | I1: HOURS PER MONTH
A2: Q.TY L=1500 | D2: ='$_BOM_CYCLE'!K4 -> 9389 | E2: WORKING DAY PER MONTH | G2: 22 | H2: SAFETY STOCK | I2: 0.2 | J2: MONTHLY REQUIREMENTS (LOAD UNITS MOVED IN A MONTH) | P2: STORAGE CAPACITY OF WAREHOUSES AND BUFFERS (PEAK INVENTORY)
A3: Q.TY L=1750 | D3: ='$_BOM_CYCLE'!K25 -> 6260 | E3: HOURS PER DATY | G3: 15
C4: CODE | D4: DESCRIPTION | J4: MODEL | L4: TOTAL | M4: LOAD UNIT TYPE | N4: PCS/LU | O4: NUM. LU | P4: BATCH | Q4: SAFETY STOCK | R4: TOTAL | S4: NUM. LU | T4: AV. INVENTORY (DAYS) | U4: TURNOVER INDEX
J5: L=1500 | K5: L=1750
A6: ITEMS IN RAW MATERIALS WAREHOUSE | C6: ='$_BOM_CYCLE'!F11 -> ESTLAM001 | D6: ='$_BOM_CYCLE'!I11 -> METAL SHEET 1500x2000x3 | J6: ='$_BOM_CYCLE'!K32 -> 1330.3666 | K6: ='$_BOM_CYCLE'!K32 -> 1330.3666 | L6: =K6+J6 -> 2660.7331 | M6: ='$_DATA'!B35 -> PALLET | N6: ='$_DATA'!J35 -> 25 | O6: =ROUNDUP((L6/N6),0) -> 107 | P6: =$L$6/($G$2/'$_DATA'!$P$34) -> 1209.4242 | Q6: =L6/$G$2*'$_DATA'!$Q$34 -> 362.82725 | R6: =P6+Q6 -> 1572.2514 | S6: =ROUNDUP(R6/N6,0) -> 63 | T6: =(P6/2+Q6)/(L6/$G$2) -> 8 | U6: =L6/(0.5*P6+Q6) -> 2.75
C7: ='$_BOM_CYCLE'!F15 -> ESTLAM002 | D7: ='$_BOM_CYCLE'!I15 -> METAL SHEET 1000x1500x3 | K7: ='$_BOM_CYCLE'!K36 -> 1662.9582 | L7: =K7+J7 -> 1662.9582 | M7: ='$_DATA'!B36 -> PALLET | N7: ='$_DATA'!J36 -> 25 | O7: =ROUNDUP((L7/N7),0) -> 67 | P7: =$L$7/($G$2/'$_DATA'!$P$34) -> 755.8901 | Q7: =L7/$G$2*'$_DATA'!$Q$34 -> 226.76703 | R7: =P7+Q7 -> 982.65713 | S7: =ROUNDUP(R7/N7,0) -> 40 | T7: =(P7/2+Q7)/(L7/$G$2) -> 8 | U7: =L7/(0.5*P7+Q7) -> 2.75
C8: ='$_BOM_CYCLE'!F19 -> ESTLAM003 | D8: ='$_BOM_CYCLE'!I19 -> METAL SHEET 1000x2000x3 | J8: ='$_BOM_CYCLE'!K19 -> 4988.3434 | K8: ='$_BOM_CYCLE'!K40 -> 3325.9164 | L8: =K8+J8 -> 8314.2598 | M8: ='$_DATA'!B37 -> PALLET | N8: ='$_DATA'!J37 -> 25 | O8: =ROUNDUP((L8/N8),0) -> 333 | P8: =$L$8/($G$2/'$_DATA'!$P$34) -> 3779.209 | Q8: =L8/$G$2*'$_DATA'!$Q$34 -> 1133.7627 | R8: =P8+Q8 -> 4912.9717 | S8: =ROUNDUP(R8/N8,0) -> 197 | T8: =(P8/2+Q8)/(L8/$G$2) -> 8 | U8: =L8/(0.5*P8+Q8) -> 2.75
C9: ='$_BOM_CYCLE'!F22 -> ESTING001 | D9: CONICAL TOOTHED WHEEL | J9: ='$_BOM_CYCLE'!K22 -> 19358.763 | K9: ='$_BOM_CYCLE'!K43 -> 12520 | L9: =K9+J9 -> 31878.763 | M9: ='$_DATA'!B39 -> NORM. | N9: ='$_DATA'!J39 -> 200 | O9: =ROUNDUP((L9/N9),0) -> 160 | P9: =$L$9/($G$2/'$_DATA'!P36) -> 4347.104 | Q9: =L9/$G$2*'$_DATA'!$Q$34 -> 4347.104 | R9: =P9+Q9 -> 8694.2081 | S9: =ROUNDUP(R9/N9,0) -> 44 | T9: =(P9/2+Q9)/(L9/$G$2) -> 4.5 | U9: =L9/(0.5*P9+Q9) -> 4.8888889
C10: ='$_BOM_CYCLE'!F23 -> ESTING002 | D10: CYLINDRICAL TOOTHED WHEEL | J10: ='$_BOM_CYCLE'!K23 -> 29038.144 | K10: ='$_BOM_CYCLE'!K44 -> 18780 | L10: =K10+J10 -> 47818.144 | M10: ='$_DATA'!B40 -> NORM. | N10: ='$_DATA'!J40 -> 200 | O10: =ROUNDUP((L10/N10),0) -> 240 | P10: =$L$10/($G$2/'$_DATA'!P36) -> 6520.656 | Q10: =L10/$G$2*'$_DATA'!$Q$34 -> 6520.656 | R10: =P10+Q10 -> 13041.312 | S10: =ROUNDUP(R10/N10,0) -> 66 | T10: =(P10/2+Q10)/(L10/$G$2) -> 4.5 | U10: =L10/(0.5*P10+Q10) -> 4.8888889
C11: ='$_BOM_CYCLE'!F21 -> ESTALB001 | D11: DRIVE SHAFT L=1500 | J11: ='$_BOM_CYCLE'!K21 -> 9679.3814 | L11: =K11+J11 -> 9679.3814 | M11: ='$_DATA'!B51 -> NORM. | N11: ='$_DATA'!J51 -> 50 | O11: =ROUNDUP((L11/N11),0) -> 194 | P11: =$L$11/($G$2/'$_DATA'!P38) -> 4399.7188 | Q11: =L11/$G$2*'$_DATA'!$Q$34 -> 1319.9157 | R11: =P11+Q11 -> 5719.6345 | S11: =ROUNDUP(R11/N11,0) -> 115 | T11: =(P11/2+Q11)/(L11/$G$2) -> 8 | U11: =L11/(0.5*P11+Q11) -> 2.75
C12: ='$_BOM_CYCLE'!F42 -> ESTALB002 | D12: DRIVE SHAFT L=1750 | K12: ='$_BOM_CYCLE'!K42 -> 6260 | L12: =K12+J12 -> 6260 | M12: ='$_DATA'!B52 -> NORM. | N12: ='$_DATA'!J52 -> 50 | O12: =ROUNDUP((L12/N12),0) -> 126 | P12: =$L$12/($G$2/'$_DATA'!P38) -> 2845.4545 | Q12: =L12/$G$2*'$_DATA'!$Q$34 -> 853.63636 | R12: =P12+Q12 -> 3699.0909 | S12: =ROUNDUP(R12/N12,0) -> 74 | T12: =(P12/2+Q12)/(L12/$G$2) -> 8 | U12: =L12/(0.5*P12+Q12) -> 2.75
C13: ='$_BOM_CYCLE'!F24 -> ESTASS003 | D13: ='$_BOM_CYCLE'!I24 -> COMPLETE SHAFT WITH HAMMERS FOR FLAIL MOWERS L=1500 | J13: ='$_BOM_CYCLE'!K24 -> 9679.3814 | L13: =K13+J13 -> 9679.3814 | M13: ='$_DATA'!B49 -> SPEC. | N13: ='$_DATA'!J49 -> 12 | O13: =ROUNDUP((L13/N13),0) -> 807 | P13: =$L$13/($G$2/'$_DATA'!P40) -> 2199.8594 | Q13: =L13/$G$2*'$_DATA'!$Q$34 -> 1319.9157 | R13: =P13+Q13 -> 3519.7751 | S13: =ROUNDUP(R13/N13,0) -> 294 | T13: =(P13/2+Q13)/(L13/$G$2) -> 5.5 | U13: =L13/(0.5*P13+Q13) -> 4
C14: ='$_BOM_CYCLE'!F45 -> ESTASS004 | D14: ='$_BOM_CYCLE'!I45 -> COMPLETE SHAFT WITH HAMMERS FOR FLAIL MOWERS L=1750 | K14: ='$_BOM_CYCLE'!K45 -> 6260 | L14: =K14+J14 -> 6260 | M14: ='$_DATA'!B50 -> SPEC. | N14: ='$_DATA'!J50 -> 12 | O14: =ROUNDUP((L14/N14),0) -> 522 | P14: =$L$14/($G$2/'$_DATA'!P40) -> 1422.7273 | Q14: =L14/$G$2*'$_DATA'!$Q$34 -> 853.63636 | R14: =P14+Q14 -> 2276.3636 | S14: =ROUNDUP(R14/N14,0) -> 190 | T14: =(P14/2+Q14)/(L14/$G$2) -> 5.5 | U14: =L14/(0.5*P14+Q14) -> 4
C15: ='$_BOM_CYCLE'!F20 -> ESTSAL001 | D15: RAKE FOR FLAIL MOWERS L=1500 | J15: ='$_BOM_CYCLE'!K20 -> 9679.3814 | L15: =K15+J15 -> 9679.3814 | M15: ='$_DATA'!B65 -> SPEC. | N15: ='$_DATA'!J65 -> 12 | O15: =ROUNDUP((L15/N15),0) -> 807 | P15: =$L$15/($G$2/'$_DATA'!P42) -> 4399.7188 | Q15: =L15/$G$2*'$_DATA'!$Q$34 -> 1319.9157 | R15: =P15+Q15 -> 5719.6345 | S15: =ROUNDUP(R15/N15,0) -> 477 | T15: =(P15/2+Q15)/(L15/$G$2) -> 8 | U15: =L15/(0.5*P15+Q15) -> 2.75
C16: ='$_BOM_CYCLE'!F41 -> ESTSAL002 | D16: RAKE FOR FLAIL MOWERS L=1750 | K16: ='$_BOM_CYCLE'!K41 -> 6453.6082 | L16: =K16+J16 -> 6453.6082 | M16: ='$_DATA'!B66 -> SPEC. | N16: ='$_DATA'!J66 -> 12 | O16: =ROUNDUP((L16/N16),0) -> 538 | P16: =$L$16/($G$2/'$_DATA'!P42) -> 2933.4583 | Q16: =L16/$G$2*'$_DATA'!$Q$34 -> 880.03749 | R16: =P16+Q16 -> 3813.4958 | S16: =ROUNDUP(R16/N16,0) -> 318 | T16: =(P16/2+Q16)/(L16/$G$2) -> 8 | U16: =L16/(0.5*P16+Q16) -> 2.75
Z17: REORDER CYCLE AND SAFETY STOCK OF MATERIALS IN RAW MATERIALS WAREHOUSE | AC17: REORDER CYCLE [DAYS] | AD17: SAFETY STOCK [DAYS]
A18: ITEMS IN PRODUCTS WAREHOUSE | C18: ='$_BOM_CYCLE'!F4 -> INTASS001 | D18: ='$_BOM_CYCLE'!I4 -> COMPLETE FLAIL MOWERS L=1500 | J18: ='$_BOM_CYCLE'!K4 -> 9389 | L18: =K18+J18 -> 9389 | M18: ='$_DATA'!B45 -> PALLET+BOXES | N18: ='$_DATA'!J45 -> 1 | O18: =ROUNDUP((L18/N18),0) -> 9389 | P18: ='$_DATA'!S47*'$_DATA'!U16 -> 500 | Q18: =P18*$I$2 -> 100 | R18: =P18+Q18 -> 600 | S18: =ROUNDUP(R18/N18,0) -> 600 | T18: =(P18/2+Q18)/(L18/$G$2) -> 0.82010864 | U18: =L18/(0.5*P18+Q18) -> 26.825714
C19: ='$_BOM_CYCLE'!F25 -> INTASS002 | D19: ='$_BOM_CYCLE'!I25 -> COMPLETE FLAIL MOWERS L=1750 | K19: ='$_BOM_CYCLE'!K25 -> 6260 | L19: =K19+J19 -> 6260 | M19: ='$_DATA'!B46 -> PALLET+BOXES | N19: ='$_DATA'!J46 -> 1 | O19: =ROUNDUP((L19/N19),0) -> 6260 | P19: ='$_DATA'!S48*'$_DATA'!U16 -> 215 | Q19: =P19*$I$2 -> 43 | R19: =P19+Q19 -> 258 | S19: =ROUNDUP(R19/N19,0) -> 258 | T19: =(P19/2+Q19)/(L19/$G$2) -> 0.52891374 | U19: =L19/(0.5*P19+Q19) -> 41.594684
Z20: METAL SHEETS | AC20: 10 | AD20: 3
A21: ITEMS IN INTERMEDIATE BUFFERS | C21: ='$_BOM_CYCLE'!F6 -> INTSAL001 | D21: ='$_BOM_CYCLE'!I6 -> COMPLETE FLAIL MOWERS FRAME L=1500 | J21: ='$_BOM_CYCLE'!K6 -> 9389 | L21: =K21+J21 -> 9389 | M21: ='$_DATA'!B47 -> SPEC. | N21: ='$_DATA'!J47 -> 4 | O21: =ROUNDUP((L21/N21),0) -> 2348 | P21: ='$_DATA'!S49*'$_DATA'!U20 -> 485 | Q21: =$I$2*P21 -> 97 | R21: =P21+Q21 -> 582 | S21: =ROUNDUP(R21/N21,0) -> 146 | T21: =(P21/2+Q21)/(L21/$G$2) -> 0.79550538 | U21: =L21/(0.5*P21+Q21) -> 27.655376
C22: ='$_BOM_CYCLE'!F27 -> INTSAL002 | D22: ='$_BOM_CYCLE'!I27 -> COMPLETE FLAIL MOWERS FRAME L=1750 | K22: ='$_BOM_CYCLE'!K27 -> 6260 | L22: =K22+J22 -> 6260 | M22: ='$_DATA'!B48 -> SPEC. | N22: ='$_DATA'!J48 -> 4 | O22: =ROUNDUP((L22/N22),0) -> 1565 | P22: ='$_DATA'!S50*'$_DATA'!U20 -> 208.55 | Q22: =$I$2*P22 -> 41.71 | R22: =P22+Q22 -> 250.26 | S22: =ROUNDUP(R22/N22,0) -> 63 | T22: =(P22/2+Q22)/(L22/$G$2) -> 0.51304633 | U22: =L22/(0.5*P22+Q22) -> 42.881118 | Z22: GEARS (CONICAL AND CYLINDRICAL) | AC22: 3 | AD22: 1
C23: ='$_BOM_CYCLE'!F8 -> INTPSP001 | D23: ='$_BOM_CYCLE'!I8 -> GUARD L=1500 | J23: ='$_BOM_CYCLE'!K8 -> 9679.3814 | L23: =K23+J23 -> 9679.3814 | M23: ='$_DATA'!B55 -> PALLET | N23: ='$_DATA'!J55 -> 25 | O23: =ROUNDUP((L23/N23),0) -> 388 | P23: ='$_DATA'!S51*'$_DATA'!U28 -> 495 | Q23: =$I$2*P23 -> 99 | R23: =P23+Q23 -> 594 | S23: =ROUNDUP(R23/N23,0) -> 24 | T23: =(P23/2+Q23)/(L23/$G$2) -> 0.78755032 | U23: =L23/(0.5*P23+Q23) -> 27.934723
C24: ='$_MANUF_PARTS_BATCH'!C14 -> INTPSP001-10 | D24: STAMPED GUARD L=1500 | J24: ='$_BOM_CYCLE'!L10 -> 9777.153 | L24: =K24+J24 -> 9777.153 | M24: ='$_DATA'!B56 -> PALLET | N24: ='$_DATA'!J56 -> 25 | O24: =ROUNDUP((L24/N24),0) -> 392 | P24: ='$_DATA'!S52*'$_DATA'!U26 -> 490 | Q24: =$I$2*P24 -> 98 | R24: =P24+Q24 -> 588 | S24: =ROUNDUP(R24/N24,0) -> 24 | T24: =(P24/2+Q24)/(L24/$G$2) -> 0.77179932 | U24: =L24/(0.5*P24+Q24) -> 28.504819 | Z24: DRIVE SHAFTS | AC24: 10 | AD24: 3
C25: ='$_BOM_CYCLE'!F29 -> INTPSP002 | D25: ='$_BOM_CYCLE'!I29 -> GUARD L=1750 | K25: ='$_BOM_CYCLE'!K29 -> 6453.6082 | L25: =K25+J25 -> 6453.6082 | M25: ='$_DATA'!B57 -> PALLET | N25: ='$_DATA'!J57 -> 25 | O25: =ROUNDUP((L25/N25),0) -> 259 | P25: ='$_DATA'!S53*'$_DATA'!U28 -> 212.85 | Q25: =$I$2*P25 -> 42.57 | R25: =P25+Q25 -> 255.42 | S25: =ROUNDUP(R25/N25,0) -> 11 | T25: =(P25/2+Q25)/(L25/$G$2) -> 0.50791586 | U25: =L25/(0.5*P25+Q25) -> 43.314261
C26: ='$_MANUF_PARTS_BATCH'!C16 -> INTPSP002-10 | D26: STAMPED GUARD L=1750 | K26: ='$_BOM_CYCLE'!L31 -> 6651.8329 | L26: =K26+J26 -> 6651.8329 | M26: ='$_DATA'!B58 -> PALLET | N26: ='$_DATA'!J58 -> 25 | O26: =ROUNDUP((L26/N26),0) -> 267 | P26: ='$_DATA'!S54*'$_DATA'!U26 -> 210.7 | Q26: =$I$2*P26 -> 42.14 | R26: =P26+Q26 -> 252.84 | S26: =ROUNDUP(R26/N26,0) -> 11 | T26: =(P26/2+Q26)/(L26/$G$2) -> 0.48780239 | U26: =L26/(0.5*P26+Q26) -> 45.10023 | Z26: COMPLETE SHAFTS WITH HAMMERS | AC26: 5 | AD26: 1
C27: ='$_BOM_CYCLE'!F12 -> INTPSP003 | D27: ='$_BOM_CYCLE'!I12 -> REINFORCEMENT BRACKETS | J27: ='$_BOM_CYCLE'!K12 -> 29038.144 | K27: ='$_BOM_CYCLE'!K33 -> 32268.041 | L27: =K27+J27 -> 61306.186 | M27: ='$_DATA'!B59 -> NORM. | N27: ='$_DATA'!J59 -> 200 | O27: =ROUNDUP((L27/N27),0) -> 307 | P27: ='$_DATA'!S55*'$_DATA'!U28 -> 2970 | Q27: =$I$2*P27 -> 594 | R27: =P27+Q27 -> 3564 | S27: =ROUNDUP(R27/N27,0) -> 18 | T27: =(P27/2+Q27)/(L27/$G$2) -> 0.74605849 | U27: =L27/(0.5*P27+Q27) -> 29.488305
C28: ='$_MANUF_PARTS_BATCH'!C18 -> INTPSP002-10 | D28: STAMPED REINFORCEMENT BRACKETS | J28: ='$_BOM_CYCLE'!L14 -> 29930.06 | K28: ='$_BOM_CYCLE'!L35 -> 33259.164 | L28: =K28+J28 -> 63189.224 | M28: ='$_DATA'!B60 -> NORM. | N28: ='$_DATA'!J60 -> 200 | O28: =ROUNDUP((L28/N28),0) -> 316 | P28: ='$_DATA'!S56*'$_DATA'!U26 -> 2940 | Q28: =$I$2*P28 -> 588 | R28: =P28+Q28 -> 3528 | S28: =ROUNDUP(R28/N28,0) -> 18 | T28: =(P28/2+Q28)/(L28/$G$2) -> 0.71651457 | U28: =L28/(0.5*P28+Q28) -> 30.704191 | Z28: RAKE FOR FLAIL MOWERS | AC28: 10 | AD28: 3
C29: ='$_BOM_CYCLE'!F16 -> INTPSP004 | D29: ='$_BOM_CYCLE'!I16 -> TRACTOR HITCHS PLATES | J29: ='$_BOM_CYCLE'!K16 -> 19358.763 | K29: ='$_BOM_CYCLE'!K37 -> 12907.216 | L29: =K29+J29 -> 32265.979 | M29: ='$_DATA'!B61 -> NORM. | N29: ='$_DATA'!J61 -> 200 | O29: =ROUNDUP((L29/N29),0) -> 162 | P29: ='$_DATA'!S57*'$_DATA'!U28 -> 1980 | Q29: =$I$2*P29 -> 396 | R29: =P29+Q29 -> 2376 | S29: =ROUNDUP(R29/N29,0) -> 12 | T29: =(P29/2+Q29)/(L29/$G$2) -> 0.94502013 | U29: =L29/(0.5*P29+Q29) -> 23.279927
C30: ='$_MANUF_PARTS_BATCH'!C20 -> INTPSP004-10 | D30: STAMPED TRACTOR HITCHS BRACKETS | J30: ='$_BOM_CYCLE'!L18 -> 19953.373 | K30: ='$_BOM_CYCLE'!L39 -> 13303.666 | L30: =K30+J30 -> 33257.039 | M30: ='$_DATA'!B62 -> NORM. | N30: ='$_DATA'!J62 -> 200 | O30: =ROUNDUP((L30/N30),0) -> 167 | P30: ='$_MANUF_PARTS_BATCH'!M20*'$_DATA'!U26 -> 1960 | Q30: =$I$2*P30 -> 392 | R30: =P30+Q30 -> 2352 | S30: =ROUNDUP(R30/N30,0) -> 12 | T30: =(P30/2+Q30)/(L30/$G$2) -> 0.90759733 | U30: =L30/(0.5*P30+Q30) -> 24.239824

Sheet ABC ANALYSIS
A1: PLANT ABC ANALYSIS
A2: Components | B2: Turnover Index | C2: Cummilative Turnover Index | D2: Cummilative Turnover Index (%)
A3: ='$_WARE_BUFFER'!D6 -> METAL SHEET 1500x2000x3 | B3: ='$_WARE_BUFFER'!U6 -> 2.75 | C3: =B3 -> 2.75 | D3: =C3/$C$25*100 -> 0.64169733
A4: ='$_WARE_BUFFER'!D8 -> METAL SHEET 1000x2000x3 | B4: ='$_WARE_BUFFER'!U8 -> 2.75 | C4: =C3+B4 -> 5.5 | D4: =C4/$C$25*100 -> 1.2833947
A5: ='$_WARE_BUFFER'!D11 -> DRIVE SHAFT L=1500 | B5: ='$_WARE_BUFFER'!U11 -> 2.75 | C5: =C4+B5 -> 8.25 | D5: =C5/$C$25*100 -> 1.925092
A6: ='$_WARE_BUFFER'!D15 -> RAKE FOR FLAIL MOWERS L=1500 | B6: ='$_WARE_BUFFER'!U15 -> 2.75 | C6: =C5+B6 -> 11 | D6: =C6/$C$25*100 -> 2.5667893
A7: ='$_WARE_BUFFER'!D7 -> METAL SHEET 1000x1500x3 | B7: ='$_WARE_BUFFER'!U7 -> 2.75 | C7: =C6+B7 -> 13.75 | D7: =C7/$C$25*100 -> 3.2084867
A8: ='$_WARE_BUFFER'!D12 -> DRIVE SHAFT L=1750 | B8: ='$_WARE_BUFFER'!U12 -> 2.75 | C8: =C7+B8 -> 16.5 | D8: =C8/$C$25*100 -> 3.850184
A9: ='$_WARE_BUFFER'!D16 -> RAKE FOR FLAIL MOWERS L=1750 | B9: ='$_WARE_BUFFER'!U16 -> 2.75 | C9: =C8+B9 -> 19.25 | D9: =C9/$C$25*100 -> 4.4918813
A10: ='$_WARE_BUFFER'!D13 -> COMPLETE SHAFT WITH HAMMERS FOR FLAIL MOWERS L=1500 | B10: ='$_WARE_BUFFER'!U13 -> 4 | C10: =C9+B10 -> 23.25 | D10: =C10/$C$25*100 -> 5.4252592
A11: ='$_WARE_BUFFER'!D14 -> COMPLETE SHAFT WITH HAMMERS FOR FLAIL MOWERS L=1750 | B11: ='$_WARE_BUFFER'!U14 -> 4 | C11: =C10+B11 -> 27.25 | D11: =C11/$C$25*100 -> 6.3586372
A12: ='$_WARE_BUFFER'!D29 -> TRACTOR HITCHS PLATES | B12: ='$_WARE_BUFFER'!U29 -> 23.279927 | C12: =C11+B12 -> 50.529927 | D12: =C12/$C$25*100 -> 11.79088
A13: ='$_WARE_BUFFER'!D30 -> STAMPED TRACTOR HITCHS BRACKETS | B13: ='$_WARE_BUFFER'!U30 -> 24.239824 | C13: =C12+B13 -> 74.769752 | D13: =C13/$C$25*100 -> 17.447109
A14: ='$_WARE_BUFFER'!D18 -> COMPLETE FLAIL MOWERS L=1500 | B14: ='$_WARE_BUFFER'!U18 -> 26.825714 | C14: =C13+B14 -> 101.59547 | D14: =C14/$C$25*100 -> 23.706742
A15: ='$_WARE_BUFFER'!D21 -> COMPLETE FLAIL MOWERS FRAME L=1500 | B15: ='$_WARE_BUFFER'!U21 -> 27.655376 | C15: =C14+B15 -> 129.25084 | D15: =C15/$C$25*100 -> 30.159971
A16: ='$_WARE_BUFFER'!D23 -> GUARD L=1500 | B16: ='$_WARE_BUFFER'!U23 -> 27.934723 | C16: =C15+B16 -> 157.18556 | D16: =C16/$C$25*100 -> 36.678384
A17: ='$_WARE_BUFFER'!D24 -> STAMPED GUARD L=1500 | B17: ='$_WARE_BUFFER'!U24 -> 28.504819 | C17: =C16+B17 -> 185.69038 | D17: =C17/$C$25*100 -> 43.329827
A18: ='$_WARE_BUFFER'!D27 -> REINFORCEMENT BRACKETS | B18: ='$_WARE_BUFFER'!U27 -> 29.488305 | C18: =C17+B18 -> 215.17869 | D18: =C18/$C$25*100 -> 50.21076
A19: ='$_WARE_BUFFER'!D28 -> STAMPED REINFORCEMENT BRACKETS | B19: ='$_WARE_BUFFER'!U28 -> 30.704191 | C19: =C18+B19 -> 245.88288 | D19: =C19/$C$25*100 -> 57.375413
A20: ='$_WARE_BUFFER'!D19 -> COMPLETE FLAIL MOWERS L=1750 | B20: ='$_WARE_BUFFER'!U19 -> 41.594684 | C20: =C19+B20 -> 287.47756 | D20: =C20/$C$25*100 -> 67.081304
A21: ='$_WARE_BUFFER'!D22 -> COMPLETE FLAIL MOWERS FRAME L=1750 | B21: ='$_WARE_BUFFER'!U22 -> 42.881118 | C21: =C20+B21 -> 330.35868 | D21: =C21/$C$25*100 -> 77.087376
A22: ='$_WARE_BUFFER'!D25 -> GUARD L=1750 | B22: ='$_WARE_BUFFER'!U25 -> 43.314261 | C22: =C21+B22 -> 373.67294 | D22: =C22/$C$25*100 -> 87.19452
A23: ='$_WARE_BUFFER'!D26 -> STAMPED GUARD L=1750 | B23: ='$_WARE_BUFFER'!U26 -> 45.10023 | C23: =C22+B23 -> 418.77317 | D23: =C23/$C$25*100 -> 97.718409
A24: ='$_WARE_BUFFER'!D9 -> CONICAL TOOTHED WHEEL | B24: ='$_WARE_BUFFER'!U9 -> 4.8888889 | C24: =C23+B24 -> 423.66206 | D24: =C24/$C$25*100 -> 98.859205
A25: ='$_WARE_BUFFER'!D10 -> CYLINDRICAL TOOTHED WHEEL | B25: ='$_WARE_BUFFER'!U10 -> 4.8888889 | C25: =C24+B25 -> 428.55095 | D25: =C25/$C$25*100 -> 100
A29: RAW MATERIAL WAREHOUSE ABC ANALYSIS
A30: Components | B30: Turnover Index | C30: Cummilative Turnover Index | D30: Cummilative Turnover Index (%)
A31: ='$_WARE_BUFFER'!D6 -> METAL SHEET 1500x2000x3 | B31: ='$_WARE_BUFFER'!U6 -> 2.75 | C31: =B31 -> 2.75 | D31: =C31/$C$41*100 -> 7.4268567
A32: ='$_WARE_BUFFER'!D7 -> METAL SHEET 1000x1500x3 | B32: ='$_WARE_BUFFER'!U7 -> 2.75 | C32: =C31+B32 -> 5.5 | D32: =C32/$C$41*100 -> 14.853713
A33: ='$_WARE_BUFFER'!D8 -> METAL SHEET 1000x2000x3 | B33: ='$_WARE_BUFFER'!U8 -> 2.75 | C33: =C32+B33 -> 8.25 | D33: =C33/$C$41*100 -> 22.28057
A34: ='$_WARE_BUFFER'!D9 -> CONICAL TOOTHED WHEEL | B34: ='$_WARE_BUFFER'!U9 -> 4.8888889 | C34: =C33+B34 -> 13.138889 | D34: =C34/$C$41*100 -> 35.483871
A35: ='$_WARE_BUFFER'!D10 -> CYLINDRICAL TOOTHED WHEEL | B35: ='$_WARE_BUFFER'!U10 -> 4.8888889 | C35: =C34+B35 -> 18.027778 | D35: =C35/$C$41*100 -> 48.687172
A36: ='$_WARE_BUFFER'!D11 -> DRIVE SHAFT L=1500 | B36: ='$_WARE_BUFFER'!U11 -> 2.75 | C36: =C35+B36 -> 20.777778 | D36: =C36/$C$41*100 -> 56.114029
A37: ='$_WARE_BUFFER'!D12 -> DRIVE SHAFT L=1750 | B37: ='$_WARE_BUFFER'!U12 -> 2.75 | C37: =C36+B37 -> 23.527778 | D37: =C37/$C$41*100 -> 63.540885
A38: ='$_WARE_BUFFER'!D13 -> COMPLETE SHAFT WITH HAMMERS FOR FLAIL MOWERS L=1500 | B38: ='$_WARE_BUFFER'!U13 -> 4 | C38: =C37+B38 -> 27.527778 | D38: =C38/$C$41*100 -> 74.343586
A39: ='$_WARE_BUFFER'!D14 -> COMPLETE SHAFT WITH HAMMERS FOR FLAIL MOWERS L=1750 | B39: ='$_WARE_BUFFER'!U14 -> 4 | C39: =C38+B39 -> 31.527778 | D39: =C39/$C$41*100 -> 85.146287
A40: ='$_WARE_BUFFER'!D15 -> RAKE FOR FLAIL MOWERS L=1500 | B40: ='$_WARE_BUFFER'!U15 -> 2.75 | C40: =C39+B40 -> 34.277778 | D40: =C40/$C$41*100 -> 92.573143
A41: ='$_WARE_BUFFER'!D16 -> RAKE FOR FLAIL MOWERS L=1750 | B41: ='$_WARE_BUFFER'!U16 -> 2.75 | C41: =C40+B41 -> 37.027778 | D41: =C41/$C$41*100 -> 100
A45: STAMPING BUFFER WAREHOUSE ABC ANALYSIS
A46: Components | B46: Turnover Index | C46: Cummilative Turnover Index | D46: Cummilative Turnover Index (%)
...

Sheet WARE_BUFFER_EPEI
A1: TOTAL Q.TY (L=1500 + L=1750) | D1: =D2+D3 -> 15649 | E1: PCS/MONTH | F1: =D1/22 -> 711.31818 | G1: PCS PER DAY | H1: ='$_DATA'!M8 -> 330 | I1: HOURS PER MONTH
A2: Q.TY L=1500 | D2: ='$_BOM_CYCLE'!K4 -> 9389 | E2: WORKING DAY PER MONTH | G2: 22 | H2: SAFETY STOCK | I2: 0.2 | J2: MONTHLY REQUIREMENTS (LOAD UNITS MOVED IN A MONTH) | P2: STORAGE CAPACITY OF WAREHOUSES AND BUFFERS (PEAK INVENTORY)
A3: Q.TY L=1750 | D3: ='$_BOM_CYCLE'!K25 -> 6260 | E3: HOURS PER DATY | G3: 15
C4: CODE | D4: DESCRIPTION | J4: MODEL | L4: TOTAL | M4: LOAD UNIT TYPE | N4: PCS/LU | O4: NUM. LU | P4: BATCH | Q4: SAFETY STOCK | R4: TOTAL | S4: NUM. LU | T4: AV. INVENTORY (DAYS) | U4: TURNOVER INDEX | V4: Reorder Cycle | W4: Safety Stock Cycle
J5: L=1500 | K5: L=1750
A6: ITEMS IN RAW MATERIALS WAREHOUSE | C6: ='$_BOM_CYCLE'!F11 -> ESTLAM001 | D6: ='$_BOM_CYCLE'!I11 -> METAL SHEET 1500x2000x3 | J6: ='$_BOM_CYCLE'!K32 -> 1330.3666 | K6: ='$_BOM_CYCLE'!K32 -> 1330.3666 | L6: =K6+J6 -> 2660.7331 | M6: ='$_DATA'!B35 -> PALLET | N6: ='$_DATA'!J35 -> 25 | O6: =ROUNDUP((L6/N6),0) -> 107 | P6: =('$_BOM_CYCLE'!K11+'$_BOM_CYCLE'!K32)/$G$2*$V$6 -> 1493.5442 | Q6: =L6/22*W$6 -> 362.82725 | R6: =P6+Q6 -> 1856.3714 | S6: =ROUNDUP(R6/N6,0) -> 75 | T6: =(P6/2+Q6)/(L6/$G$2) -> 9.1746086 | U6: =L6/(0.5*P6+Q6) -> 2.3979225 | V6: 10 | W6: 3
C7: ='$_BOM_CYCLE'!F15 -> ESTLAM002 | D7: ='$_BOM_CYCLE'!I15 -> METAL SHEET 1000x1500x3 | K7: ='$_BOM_CYCLE'!K36 -> 1662.9582 | L7: =K7+J7 -> 1662.9582 | M7: ='$_DATA'!B36 -> PALLET | N7: ='$_DATA'!J36 -> 25 | O7: =ROUNDUP((L7/N7),0) -> 67 | P7: =('$_BOM_CYCLE'!K15+'$_BOM_CYCLE'!K36)/$G$2*$V$6 -> 1436.1187 | Q7: =L7/22*W$6 -> 226.76703 | R7: =P7+Q7 -> 1662.8858 | S7: =ROUNDUP(R7/N7,0) -> 67 | T7: =(P7/2+Q7)/(L7/$G$2) -> 12.499521 | U7: =L7/(0.5*P7+Q7) -> 1.7600675
C8: ='$_BOM_CYCLE'!F19 -> ESTLAM003 | D8: ='$_BOM_CYCLE'!I19 -> METAL SHEET 1000x2000x3 | J8: ='$_BOM_CYCLE'!K19 -> 4988.3434 | K8: ='$_BOM_CYCLE'!K40 -> 3325.9164 | L8: =K8+J8 -> 8314.2598 | M8: ='$_DATA'!B37 -> PALLET | N8: ='$_DATA'!J37 -> 25 | O8: =ROUNDUP((L8/N8),0) -> 333 | P8: =('$_BOM_CYCLE'!K19+'$_BOM_CYCLE'!K40)/$G$2*$V$6 -> 3779.209 | Q8: =L8/22*W6 -> 1133.7627 | R8: =P8+Q8 -> 4912.9717 | S8: =ROUNDUP(R8/N8,0) -> 197 | T8: =(P8/2+Q8)/(L8/$G$2) -> 8 | U8: =L8/(0.5*P8+Q8) -> 2.75
C9: ='$_BOM_CYCLE'!F22 -> ESTING001 | D9: CONICAL TOOTHED WHEEL | J9: ='$_BOM_CYCLE'!K22 -> 19358.763 | K9: ='$_BOM_CYCLE'!K43 -> 12520 | L9: =K9+J9 -> 31878.763 | M9: ='$_DATA'!B39 -> NORM. | N9: ='$_DATA'!J39 -> 200 | O9: =ROUNDUP((L9/N9),0) -> 160 | P9: =('$_BOM_CYCLE'!K22+'$_BOM_CYCLE'!K43)/$G$2*$V$9 -> 4347.104 | Q9: =L9/22*W9 -> 1449.0347 | R9: =P9+Q9 -> 5796.1387 | S9: =ROUNDUP(R9/N9,0) -> 29 | T9: =(P9/2+Q9)/(L9/$G$2) -> 2.5 | U9: =L9/(0.5*P9+Q9) -> 8.8 | V9: 3 | W9: 1
C10: ='$_BOM_CYCLE'!F23 -> ESTING002 | D10: CYLINDRICAL TOOTHED WHEEL | J10: ='$_BOM_CYCLE'!K23 -> 29038.144 | K10: ='$_BOM_CYCLE'!K44 -> 18780 | L10: =K10+J10 -> 47818.144 | M10: ='$_DATA'!B40 -> NORM. | N10: ='$_DATA'!J40 -> 200 | O10: =ROUNDUP((L10/N10),0) -> 240 | P10: =('$_BOM_CYCLE'!K23+'$_BOM_CYCLE'!K44)/$G$2*$V$9 -> 6520.656 | Q10: =L10/22*W$9 -> 2173.552 | R10: =P10+Q10 -> 8694.2081 | S10: =ROUNDUP(R10/N10,0) -> 44 | T10: =(P10/2+Q10)/(L10/$G$2) -> 2.5 | U10: =L10/(0.5*P10+Q10) -> 8.8
C11: ='$_BOM_CYCLE'!F21 -> ESTALB001 | D11: DRIVE SHAFT L=1500 | J11: ='$_BOM_CYCLE'!K21 -> 9679.3814 | L11: =K11+J11 -> 9679.3814 | M11: ='$_DATA'!B51 -> NORM. | N11: ='$_DATA'!J51 -> 50 | O11: =ROUNDUP((L11/N11),0) -> 194 | P11: =('$_BOM_CYCLE'!K21)/$G$2*$V$11 -> 4399.7188 | Q11: =L11/22*W$11 -> 1319.9157 | R11: =P11+Q11 -> 5719.6345 | S11: =ROUNDUP(R11/N11,0) -> 115 | T11: =(P11/2+Q11)/(L11/$G$2) -> 8 | U11: =L11/(0.5*P11+Q11) -> 2.75 | V11: 10 | W11: 3
C12: ='$_BOM_CYCLE'!F42 -> ESTALB002 | D12: DRIVE SHAFT L=1750 | K12: ='$_BOM_CYCLE'!K42 -> 6260 | L12: =K12+J12 -> 6260 | M12: ='$_DATA'!B52 -> NORM. | N12: ='$_DATA'!J52 -> 50 | O12: =ROUNDUP((L12/N12),0) -> 126 | P12: =('$_BOM_CYCLE'!K42)/$G$2*$V$11 -> 2845.4545 | Q12: =L12/22*W$11 -> 853.63636 | R12: =P12+Q12 -> 3699.0909 | S12: =ROUNDUP(R12/N12,0) -> 74 | T12: =(P12/2+Q12)/(L12/$G$2) -> 8 | U12: =L12/(0.5*P12+Q12) -> 2.75
C13: ='$_BOM_CYCLE'!F24 -> ESTASS003 | D13: ='$_BOM_CYCLE'!I24 -> COMPLETE SHAFT WITH HAMMERS FOR FLAIL MOWERS L=1500 | J13: ='$_BOM_CYCLE'!K24 -> 9679.3814 | L13: =K13+J13 -> 9679.3814 | M13: ='$_DATA'!B49 -> SPEC. | N13: ='$_DATA'!J49 -> 12 | O13: =ROUNDUP((L13/N13),0) -> 807 | P13: =('$_BOM_CYCLE'!K24)/$G$2*$V$13 -> 2199.8594 | Q13: =L13/22*W13 -> 439.97188 | R13: =P13+Q13 -> 2639.8313 | S13: =ROUNDUP(R13/N13,0) -> 220 | T13: =(P13/2+Q13)/(L13/$G$2) -> 3.5 | U13: =L13/(0.5*P13+Q13) -> 6.2857143 | V13: 5 | W13: 1
C14: ='$_BOM_CYCLE'!F45 -> ESTASS004 | D14: ='$_BOM_CYCLE'!I45 -> COMPLETE SHAFT WITH HAMMERS FOR FLAIL MOWERS L=1750 | K14: ='$_BOM_CYCLE'!K45 -> 6260 | L14: =K14+J14 -> 6260 | M14: ='$_DATA'!B50 -> SPEC. | N14: ='$_DATA'!J50 -> 12 | O14: =ROUNDUP((L14/N14),0) -> 522 | P14: =('$_BOM_CYCLE'!K45)/$G$2*$V$13 -> 1422.7273 | Q14: =L14/22*W13 -> 284.54545 | R14: =P14+Q14 -> 1707.2727 | S14: =ROUNDUP(R14/N14,0) -> 143 | T14: =(P14/2+Q14)/(L14/$G$2) -> 3.5 | U14: =L14/(0.5*P14+Q14) -> 6.2857143
C15: ='$_BOM_CYCLE'!F20 -> ESTSAL001 | D15: RAKE FOR FLAIL MOWERS L=1500 | J15: ='$_BOM_CYCLE'!K20 -> 9679.3814 | L15: =K15+J15 -> 9679.3814 | M15: ='$_DATA'!B65 -> SPEC. | N15: ='$_DATA'!J65 -> 12 | O15: =ROUNDUP((L15/N15),0) -> 807 | P15: ='$_BOM_CYCLE'!K20*10/22 -> 4399.7188 | Q15: =L15/22*W15 -> 1319.9157 | R15: =P15+Q15 -> 5719.6345 | S15: =ROUNDUP(R15/N15,0) -> 477 | T15: =(P15/2+Q15)/(L15/$G$2) -> 8 | U15: =L15/(0.5*P15+Q15) -> 2.75 | V15: 10 | W15: 3
C16: ='$_BOM_CYCLE'!F41 -> ESTSAL002 | D16: RAKE FOR FLAIL MOWERS L=1750 | K16: ='$_BOM_CYCLE'!K41 -> 6453.6082 | L16: =K16+J16 -> 6453.6082 | M16: ='$_DATA'!B66 -> SPEC. | N16: ='$_DATA'!J66 -> 12 | O16: =ROUNDUP((L16/N16),0) -> 538 | P16: ='$_BOM_CYCLE'!K41*10/22 -> 2933.4583 | Q16: =L16/22*W15 -> 880.03749 | R16: =P16+Q16 -> 3813.4958 | S16: =ROUNDUP(R16/N16,0) -> 318 | T16: =(P16/2+Q16)/(L16/$G$2) -> 8 | U16: =L16/(0.5*P16+Q16) -> 2.75
V17: Shipping Frequency
A18: ITEMS IN PRODUCTS WAREHOUSE | C18: ='$_BOM_CYCLE'!F4 -> INTASS001 | D18: ='$_BOM_CYCLE'!I4 -> COMPLETE FLAIL MOWERS L=1500 | J18: ='$_BOM_CYCLE'!K4 -> 9389 | L18: =K18+J18 -> 9389 | M18: ='$_DATA'!B45 -> PALLET+BOXES | N18: ='$_DATA'!J45 -> 1 | O18: =ROUNDUP((L18/N18),0) -> 9389 | P18: ='$_MANUF_PARTS_BATCH'!J56*WARE_BUFFER_EPEI!V18 -> 683.56957 | Q18: =P18*$I$2 -> 136.71391 | R18: =P18+Q18 -> 820.28349 | S18: =ROUNDUP(R18/N18,0) -> 821 | T18: =(P18/2+Q18)/(L18/$G$2) -> 1.1212026 | U18: =L18/(0.5*P18+Q18) -> 19.621788 | V18: 1
C19: ='$_BOM_CYCLE'!F25 -> INTASS002 | D19: ='$_BOM_CYCLE'!I25 -> COMPLETE FLAIL MOWERS L=1750 | K19: ='$_BOM_CYCLE'!K25 -> 6260 | L19: =K19+J19 -> 6260 | M19: ='$_DATA'!B46 -> PALLET+BOXES | N19: ='$_DATA'!J46 -> 1 | O19: =ROUNDUP((L19/N19),0) -> 6260 | P19: ='$_MANUF_PARTS_BATCH'!J57*V18 -> 456.7778 | Q19: =P19*$I$2 -> 91.35556 | R19: =P19+Q19 -> 548.13336 | S19: =ROUNDUP(R19/N19,0) -> 549 | T19: =(P19/2+Q19)/(L19/$G$2) -> 1.1237026 | U19: =L19/(0.5*P19+Q19) -> 19.578134
A21: ITEMS IN INTERMEDIATE BUFFERS | C21: ='$_BOM_CYCLE'!F6 -> INTSAL001 | D21: ='$_BOM_CYCLE'!I6 -> COMPLETE FLAIL MOWERS FRAME L=1500 | J21: ='$_BOM_CYCLE'!K6 -> 9389 | L21: =K21+J21 -> 9389 | M21: ='$_DATA'!B47 -> SPEC. | N21: ='$_DATA'!J47 -> 4 | O21: =ROUNDUP((L21/N21),0) -> 2348 | P21: ='$_MANUF_PARTS_BATCH'!S55 -> 441.69316 | Q21: =$I$2*P21 -> 88.338631 | R21: =P21+Q21 -> 530.03179 | S21: =ROUNDUP(R21/N21,0) -> 133 | T21: =(P21/2+Q21)/(L21/$G$2) -> 0.72447275 | U21: =L21/(0.5*P21+Q21) -> 30.366912 | V21: 1
C22: ='$_BOM_CYCLE'!F27 -> INTSAL002 | D22: ='$_BOM_CYCLE'!I27 -> COMPLETE FLAIL MOWERS FRAME L=1750 | K22: ='$_BOM_CYCLE'!K27 -> 6260 | L22: =K22+J22 -> 6260 | M22: ='$_DATA'!B48 -> SPEC. | N22: ='$_DATA'!J48 -> 4 | O22: =ROUNDUP((L22/N22),0) -> 1565 | P22: ='$_MANUF_PARTS_BATCH'!S56 -> 297.13903 | Q22: =$I$2*P22 -> 59.427807 | R22: =P22+Q22 -> 356.56684 | S22: =ROUNDUP(R22/N22,0) -> 90 | T22: =(P22/2+Q22)/(L22/$G$2) -> 0.73098101 | U22: =L22/(0.5*P22+Q22) -> 30.096541
C23: ='$_BOM_CYCLE'!F8 -> INTPSP001 | D23: ='$_BOM_CYCLE'!I8 -> GUARD L=1500 | J23: ='$_BOM_CYCLE'!K8 -> 9679.3814 | L23: =K23+J23 -> 9679.3814 | M23: ='$_DATA'!B55 -> PALLET | N23: ='$_DATA'!J55 -> 25 | O23: =ROUNDUP((L23/N23),0) -> 388 | P23: ='$_MANUF_PARTS_BATCH'!AL55 -> 779.44573 | Q23: =$I$2*P23 -> 155.88915 | R23: =P23+Q23 -> 935.33487 | S23: =ROUNDUP(R23/N23,0) -> 38 | T23: =(P23/2+Q23)/(L23/$G$2) -> 1.2401065 | U23: =L23/(0.5*P23+Q23) -> 17.740411
C24: ='$_MANUF_PARTS_BATCH'!C14 -> INTPSP001-10 | D24: STAMPED GUARD L=1500 | J24: ='$_BOM_CYCLE'!L10 -> 9777.153 | L24: =K24+J24 -> 9777.153 | M24: ='$_DATA'!B56 -> PALLET | N24: ='$_DATA'!J56 -> 25 | O24: =ROUNDUP((L24/N24),0) -> 392 | P24: ='$_MANUF_PARTS_BATCH'!AF65 -> 843.66153 | Q24: =$I$2*P24 -> 168.73231 | R24: =P24+Q24 -> 1012.3938 | S24: =ROUNDUP(R24/N24,0) -> 41 | T24: =(P24/2+Q24)/(L24/$G$2) -> 1.3288518 | U24: =L24/(0.5*P24+Q24) -> 16.555646
C25: ='$_BOM_CYCLE'!F29 -> INTPSP002 | D25: ='$_BOM_CYCLE'!I29 -> GUARD L=1750 | K25: ='$_BOM_CYCLE'!K29 -> 6453.6082 | L25: =K25+J25 -> 6453.6082 | M25: ='$_DATA'!B57 -> PALLET | N25: ='$_DATA'!J57 -> 25 | O25: =ROUNDUP((L25/N25),0) -> 259 | P25: ='$_MANUF_PARTS_BATCH'!AL57 -> 519.63048 | Q25: =$I$2*P25 -> 103.9261 | R25: =P25+Q25 -> 623.55658 | S25: =ROUNDUP(R25/N25,0) -> 25 | T25: =(P25/2+Q25)/(L25/$G$2) -> 1.2399745 | U25: =L25/(0.5*P25+Q25) -> 17.742301
C26: ='$_MANUF_PARTS_BATCH'!C16 -> INTPSP002-10 | D26: STAMPED GUARD L=1750 | K26: ='$_BOM_CYCLE'!L31 -> 6651.8329 | L26: =K26+J26 -> 6651.8329 | M26: ='$_DATA'!B58 -> PALLET | N26: ='$_DATA'!J58 -> 25 | O26: =ROUNDUP((L26/N26),0) -> 267 | P26: ='$_MANUF_PARTS_BATCH'!AF66 -> 571.87795 | Q26: =$I$2*P26 -> 114.37559 | R26: =P26+Q26 -> 686.25354 | S26: =ROUNDUP(R26/N26,0) -> 28 | T26: =(P26/2+Q26)/(L26/$G$2) -> 1.323984 | U26: =L26/(0.5*P26+Q26) -> 16.616515
C27: ='$_BOM_CYCLE'!F12 -> INTPSP003 | D27: ='$_BOM_CYCLE'!I12 -> REINFORCEMENT BRACKETS | J27: ='$_BOM_CYCLE'!K12 -> 29038.144 | K27: ='$_BOM_CYCLE'!K33 -> 32268.041 | L27: =K27+J27 -> 61306.186 | M27: ='$_DATA'!B59 -> NORM. | N27: ='$_DATA'!J59 -> 200 | O27: =ROUNDUP((L27/N27),0) -> 307 | P27: ='$_MANUF_PARTS_BATCH'!AL56 -> 4926.097 | Q27: =$I$2*P27 -> 985.2194 | R27: =P27+Q27 -> 5911.3164 | S27: =ROUNDUP(R27/N27,0) -> 30 | T27: =(P27/2+Q27)/(L27/$G$2) -> 1.2374264 | U27: =L27/(0.5*P27+Q27) -> 17.778835
C28: ='$_MANUF_PARTS_BATCH'!C18 -> INTPSP002-10 | D28: STAMPED REINFORCEMENT BRACKETS | J28: ='$_BOM_CYCLE'!L14 -> 29930.06 | K28: ='$_BOM_CYCLE'!L35 -> 33259.164 | L28: =K28+J28 -> 63189.224 | M28: ='$_DATA'!B60 -> NORM. | N28: ='$_DATA'!J60 -> 200 | O28: =ROUNDUP((L28/N28),0) -> 316 | P28: ='$_MANUF_PARTS_BATCH'!AF67 -> 5424.3473 | Q28: =$I$2*P28 -> 1084.8695 | R28: =P28+Q28 -> 6509.2167 | S28: =ROUNDUP(R28/N28,0) -> 33 | T28: =(P28/2+Q28)/(L28/$G$2) -> 1.3219809 | U28: =L28/(0.5*P28+Q28) -> 16.641693
C29: ='$_BOM_CYCLE'!F16 -> INTPSP004 | D29: ='$_BOM_CYCLE'!I16 -> TRACTOR HITCHS PLATES | J29: ='$_BOM_CYCLE'!K16 -> 19358.763 | K29: ='$_BOM_CYCLE'!K37 -> 12907.216 | L29: =K29+J29 -> 32265.979 | M29: ='$_DATA'!B61 -> NORM. | N29: ='$_DATA'!J61 -> 200 | O29: =ROUNDUP((L29/N29),0) -> 162 | P29: ='$_MANUF_PARTS_BATCH'!AL58 -> 2592.9561 | Q29: =$I$2*P29 -> 518.59122 | R29: =P29+Q29 -> 3111.5473 | S29: =ROUNDUP(R29/N29,0) -> 16 | T29: =(P29/2+Q29)/(L29/$G$2) -> 1.2375736 | U29: =L29/(0.5*P29+Q29) -> 17.776721
C30: ='$_MANUF_PARTS_BATCH'!C20 -> INTPSP004-10 | D30: STAMPED TRACTOR HITCHS BRACKETS | J30: ='$_BOM_CYCLE'!L18 -> 19953.373 | K30: ='$_BOM_CYCLE'!L39 -> 13303.666 | L30: =K30+J30 -> 33257.039 | M30: ='$_DATA'!B62 -> NORM. | N30: ='$_DATA'!J62 -> 200 | O30: =ROUNDUP((L30/N30),0) -> 167 | P30: ='$_MANUF_PARTS_BATCH'!AF68 -> 2853.7276 | Q30: =$I$2*P30 -> 570.74552 | R30: =P30+Q30 -> 3424.4731 | S30: =ROUNDUP(R30/N30,0) -> 18 | T30: =(P30/2+Q30)/(L30/$G$2) -> 1.3214467 | U30: =L30/(0.5*P30+Q30) -> 16.64842

Sheet Recieving
C1: Receiving area calculation | K1: Step 1 | Y1: Step 2
B2: Lorry volume | C2: FEU | D2: 63.4 | E2: m3 | AA2: monday
L3: Receiving timetable | AA3: Lu | AB3: 795 | AC3: =D7+D12 -> 123
B4: Finding worst case scenario | AA4: size | AB4: 1*2*1 | AC4: 0.8x1x0.8
D5: LU received | E5: Interval | G5: Total volume | K5: Monday | L5: Volume | M5: Tuesday | N5: Volume | O5: Wednesday | P5: Volume | Q5: Thursday | R5: Volume | S5: Friday | T5: Volume | AA5: Lu/LENGTH | AB5: =12.2 -> 12.2 | AC5: =12.2/0.8 -> 15.25
A6: FM | B6: METAL SHEETS | D6: =WARE_BUFFER_EPEI!S6+WARE_BUFFER_EPEI!S7+WARE_BUFFER_EPEI!S8 -> 339 | E6: 10 | G6: =75*1.5*2*0.3+67*1.5*0.3+197*2*0.3 -> 215.85 | H6: m3 | K6: =D9 -> 795 | L6: =G9 -> 1590 | M6: =D11 -> 333 | N6: =G11 -> 208.5 | O6: =D6 -> 339 | P6: =G6 -> 215.85 | Q6: =D8 -> 189 | R6: =G8 -> 94.316 | S6: =D10 -> 363 | T6: =G10 -> 726 | AA6: Lu/width | AB6: =2.4/2 -> 1.2 | AC6: =2.4/1 -> 2.4
B7: GEARS | D7: =WARE_BUFFER_EPEI!S9+WARE_BUFFER_EPEI!S10 -> 73 | E7: 3 | G7: =D7*0.8*0.8 -> 46.72 | M7: =D7 -> 73 | N7: =G7 -> 46.72 | Q7: =D14 -> 285 | R7: =G14 -> 570 | S7: =D7 -> 73 | T7: =G7 -> 46.72 | AA7: Lu/height | AB7: =2.6 -> 2.6 | AC7: =2.6/0.8 -> 3.25
B8: DRIVE SHAFTS | D8: =WARE_BUFFER_EPEI!S11+WARE_BUFFER_EPEI!S12 -> 189 | E8: 10 | G8: =115*0.46*0.8*0.55+74*0.8*0.8*1.5 -> 94.316 | M8: =D12 -> 50 | N8: =G12 -> 32 | Q8: =D13 -> 128 | R8: =G13 -> 54.696 | S8: =D12 -> 50 | T8: =G12 -> 32 | AA8: Lu/truck | AB8: =12*1*2 -> 24 | AC8: =15*2*3 -> 90
A9: RAKE FOR FLAIL MOWERS | D9: =WARE_BUFFER_EPEI!S15+WARE_BUFFER_EPEI!S16 -> 795 | E9: 10 | G9: =D9*2 -> 1590
B10: COMPLETE SHAFTS WITH HAMMERS | D10: =WARE_BUFFER_EPEI!S13+WARE_BUFFER_EPEI!S14 -> 363 | E10: 5 | G10: =D10*2 -> 726 | AA10: Truck/day | AB10: =AB3/AB8 -> 33.125 | AC10: =AC3/AC8 -> 1.3666667
A11: RT | B11: METAL SHEETS | D11: =53+48+232 -> 333 | E11: 10 | G11: =53*1.5*2*0.3+48*1.5*0.3+232*2*0.3 -> 208.5 | J11: Sum(total load units received daily) | K11: =K6 -> 795 | L11: =L6 -> 1590 | M11: =SUM(M6:M8) -> 456 | N11: =SUM(N6:N8) -> 287.22 | O11: =O6 -> 339 | P11: =P6 -> 215.85 | Q11: =SUM(Q6:Q7) -> 474 | R11: =SUM(R6:R8) -> 719.012 | S11: =SUM(S6:S8) -> 486 | T11: =SUM(T6:T8) -> 804.72 | AB11: 34 | AC11: 2
B12: GEARS | D12: =20+30 -> 50 | E12: 3 | G12: =0.8*0.8*D12 -> 32 | AA12: total/day | AB12: 36
B13: DRIVE SHAFTS | D13: =90+38 -> 128 | E13: 10 | G13: =0.46*0.8*0.55*90+38*0.8*0.8*1.5 -> 54.696 | K13: Monday | L13: Volume | M13: Tuesday | N13: Volume | O13: Wednesday | P13: Volume | Q13: Thursday | R13: Volume | S13: Friday | T13: Volume | AA13: truck/hour | AB13: =AB12/15 -> 2.4 | AC13: take 3
B14: COMPLETE SHAFTS WITH HOES | D14: =201+84 -> 285 | E14: 5 | G14: =2*D14 -> 570 | O14: =D7 -> 73 | P14: =T7 -> 46.72 | Q14: =D14 -> 285 | R14: =R7 -> 570 | S14: =S6 -> 363 | T14: =T6 -> 726 | AA14: Docks | AB14: 3
O15: =D12 -> 50 | P15: =T8 -> 32
A17: Step 3
B18: Calculating with worst case scenario(Greatest LU number)
O19: =SUM(O14:O15) -> 123 | P19: =SUM(P14:P15) -> 78.72 | Q19: =SUM(Q14:Q15) -> 285 | R19: =SUM(R14:R15) -> 570 | S19: =SUM(S14:S15) -> 363 | T19: =SUM(T14:T15) -> 726
B20: Q | C20: =K27 -> 918 | D20: Lu/day
B21: Lu/hour | C21: =C20/15 -> 61.2 | D21: Lu/hour | K21: Monday | L21: Volume | M21: Tuesday | N21: Volume | O21: Wednesday | P21: Volume | Q21: Thursday | R21: Volume | S21: Friday | T21: Volume
B22: ts | C22: 45 | D22: min | E22: 0.75 | F22: hr | G22: loading/unloading time | K22: =D9 -> 795 | L22: =L6 -> 1590 | M22: =D11 -> 333 | N22: =N6 -> 208.5 | O22: =D6 -> 339 | P22: =P6 -> 215.85 | Q22: =D8 -> 189 | R22: =R6 -> 94.316 | S22: =S14 -> 363 | T22: =T14 -> 726
B23: tm | C23: 45 | D23: min | E23: 0.75 | F23: hr | G23: handling time inside warehouse | K23: =D7 -> 73 | L23: =T7 -> 46.72 | Q23: =D14 -> 285 | R23: =R14 -> 570
B24: Truck volume | C24: 63.4 | D24: m3 | K24: =D12 -> 50 | L24: =T8 -> 32 | Q24: =D13 -> 128 | R24: =R8 -> 54.696
B25: N.o trucks/day | C25: =ROUNDUP(L27/C24,0) -> 27 | D25: trucks/day | Q25: =D7 -> 73 | R25: =T7 -> 46.72
B26: Max size Lu | C26: 1x2x1 | E26: Oversizing with the max LU dimension | Q26: =D12 -> 50 | R26: =T8 -> 32
B27: M | C27: 3 | D27: trucks/hour | E27: (Taken from Wednesday calculation) | K27: =SUM(K22:K24) -> 918 | L27: =SUM(L22:L26) -> 1668.72 | M27: =SUM(M22:M26) -> 333 | N27: =SUM(N22:N26) -> 208.5 | O27: =SUM(O22:O26) -> 339 | P27: =SUM(P22:P26) -> 215.85 | Q27: =SUM(Q22:Q26) -> 725 | R27: =SUM(R22:R26) -> 797.732 | S27: =SUM(S22:S26) -> 363 | T27: =SUM(T22:T26) -> 726
B28: Q | C28: =ROUNDUP(K27/15,0) -> 62 | D28: LU/hour
B29: N.o docks | C29: =ROUNDUP(C27*E22,0) -> 3 | D29: docks | K29: Monday | L29: Volume | M29: Tuesday | N29: Volume | O29: Wednesday | P29: Volume | Q29: Thursday | R29: Volume | S29: Friday | T29: Volume
B30: Area | C30: =C28*E23*2*1 -> 93 | D30: m2 | M30: =D7 -> 73 | N30: =T7 -> 46.72 | Q30: =D14 -> 285 | R30: =R23 -> 570 | S30: =S22 -> 363 | T30: =T22 -> 726
B31: Buffer area per each dock | C31: =C30/C29 -> 31 | D31: m2 | M31: =D12 -> 50 | N31: =T8 -> 32 | S31: =D7 -> 73 | T31: =T7 -> 46.72
S32: =D12 -> 50 | T32: =T8 -> 32
C35: We choose the 90 degree parking | M35: =SUM(M30:M34) -> 123 | N35: =SUM(N30:N34) -> 78.72 | Q35: =SUM(Q30:Q34) -> 285 | R35: =SUM(R30:R34) -> 570 | S35: =SUM(S30:S34) -> 486 | T35: =SUM(T30:T34) -> 804.72
B36: N.O docks | C36: 3
B37: Width of truck | C37: 2.4 | D37: m
B38: Clearance | C38: 0.5 | D38: m | E38: (clearance on each side)
B39: Width of dock | C39: 3.4 | D39: m

Sheet Shipping
C2: Shipping area calculation
B4: FEU lorry | C4: 63.4 | D4: m3
C6: Lu shipped | D6: Volume
B7: FM | C7: =WARE_BUFFER_EPEI!S18+WARE_BUFFER_EPEI!S19 -> 1370 | D7: =C7*1.5*2*1 -> 4110 | E7: m3
B8: RT | C8: =360 -> 360 | D8: =C8*1.5*2*1 -> 1080 | E8: m3
B11: Calculation for total LU
B12: Q | C12: =C7+C8 -> 1730 | D12: LU/day
B13: Q(hour) | C13: =ROUNDUP(C12/15,0) -> 116 | D13: Lu/hour
B14: ts | C14: 0.75 | D14: hr
B15: tm | C15: 0.75 | D15: hr
B16: Truck V | C16: 63.4 | D16: m3
B17: Max Lu size | C17: 1.5x2x1
B18: N.o trucks | C18: =ROUNDUP(5190/C16,0) -> 82 | D18: Trucks/day
B19: M | C19: =ROUNDUP(C18/15,0) -> 6 | D19: trucks/hour
B20: N.o docks | C20: =ROUNDUP(C19*C14,0) -> 5 | D20: docks
B21: Area | C21: =C14*C13*1.5*2 -> 261 | D21: m2 | F21: =C21/2.6 -> 100.38462
